Failure # 1 (occurred at 2021-05-01_02-58-45)
Traceback (most recent call last):
  File "/zhome/45/c/127804/02460/python384/lib/python3.8/site-packages/ray/tune/trial_runner.py", line 702, in _process_trial
    results = self.trial_executor.fetch_result(trial)
  File "/zhome/45/c/127804/02460/python384/lib/python3.8/site-packages/ray/tune/ray_trial_executor.py", line 686, in fetch_result
    result = ray.get(trial_future[0], timeout=DEFAULT_GET_TIMEOUT)
  File "/zhome/45/c/127804/02460/python384/lib/python3.8/site-packages/ray/_private/client_mode_hook.py", line 47, in wrapper
    return func(*args, **kwargs)
  File "/zhome/45/c/127804/02460/python384/lib/python3.8/site-packages/ray/worker.py", line 1481, in get
    raise value.as_instanceof_cause()
ray.exceptions.RayTaskError(TuneError): [36mray::ImplicitFunc.train_buffered()[39m (pid=25670, ip=10.66.20.2)
  File "python/ray/_raylet.pyx", line 505, in ray._raylet.execute_task
  File "python/ray/_raylet.pyx", line 449, in ray._raylet.execute_task.function_executor
  File "/zhome/45/c/127804/02460/python384/lib/python3.8/site-packages/ray/_private/function_manager.py", line 556, in actor_method_executor
    return method(__ray_actor, *args, **kwargs)
  File "/zhome/45/c/127804/02460/python384/lib/python3.8/site-packages/ray/tune/trainable.py", line 173, in train_buffered
    result = self.train()
  File "/zhome/45/c/127804/02460/python384/lib/python3.8/site-packages/ray/tune/trainable.py", line 232, in train
    result = self.step()
  File "/zhome/45/c/127804/02460/python384/lib/python3.8/site-packages/ray/tune/function_runner.py", line 366, in step
    self._report_thread_runner_error(block=True)
  File "/zhome/45/c/127804/02460/python384/lib/python3.8/site-packages/ray/tune/function_runner.py", line 512, in _report_thread_runner_error
    raise TuneError(
ray.tune.error.TuneError: Trial raised an exception. Traceback:
[36mray::ImplicitFunc.train_buffered()[39m (pid=25670, ip=10.66.20.2)
  File "/zhome/45/c/127804/02460/python384/lib/python3.8/site-packages/ray/tune/function_runner.py", line 248, in run
    self._entrypoint()
  File "/zhome/45/c/127804/02460/python384/lib/python3.8/site-packages/ray/tune/function_runner.py", line 315, in entrypoint
    return self._trainable_func(self.config, self._status_reporter,
  File "/zhome/45/c/127804/02460/python384/lib/python3.8/site-packages/ray/tune/function_runner.py", line 580, in _trainable_func
    output = fn()
  File "grid_search_warm_up.py", line 94, in train_func
    loss, rl, kl      = vae.loss(x_hat, batch,p_mu,p_logvar,d_mu,d_logvar,alpha_warm_up =alpha_warm_up[k])
  File "/zhome/45/c/127804/02460/Variational_proteins/HVAE_v2.py", line 183, in loss
    p = Normal(p_mu[i], p_logvar[i].mul(1/2).exp())
  File "/zhome/45/c/127804/02460/python384/lib/python3.8/site-packages/torch/distributions/normal.py", line 50, in __init__
    super(Normal, self).__init__(batch_shape, validate_args=validate_args)
  File "/zhome/45/c/127804/02460/python384/lib/python3.8/site-packages/torch/distributions/distribution.py", line 53, in __init__
    raise ValueError("The parameter {} has invalid values".format(param))
ValueError: The parameter loc has invalid values

