Failure # 1 (occurred at 2021-04-22_16-55-45)
Traceback (most recent call last):
  File "/zhome/b8/a/122402/VAE-protein/vae_env/lib/python3.8/site-packages/ray/tune/trial_runner.py", line 586, in _process_trial
    results = self.trial_executor.fetch_result(trial)
  File "/zhome/b8/a/122402/VAE-protein/vae_env/lib/python3.8/site-packages/ray/tune/ray_trial_executor.py", line 609, in fetch_result
    result = ray.get(trial_future[0], timeout=DEFAULT_GET_TIMEOUT)
  File "/zhome/b8/a/122402/VAE-protein/vae_env/lib/python3.8/site-packages/ray/_private/client_mode_hook.py", line 47, in wrapper
    return func(*args, **kwargs)
  File "/zhome/b8/a/122402/VAE-protein/vae_env/lib/python3.8/site-packages/ray/worker.py", line 1456, in get
    raise value.as_instanceof_cause()
ray.exceptions.RayTaskError(TuneError): [36mray::ImplicitFunc.train_buffered()[39m (pid=25266, ip=10.66.20.9)
  File "python/ray/_raylet.pyx", line 480, in ray._raylet.execute_task
  File "python/ray/_raylet.pyx", line 432, in ray._raylet.execute_task.function_executor
  File "/zhome/b8/a/122402/VAE-protein/vae_env/lib/python3.8/site-packages/ray/tune/trainable.py", line 167, in train_buffered
    result = self.train()
  File "/zhome/b8/a/122402/VAE-protein/vae_env/lib/python3.8/site-packages/ray/tune/trainable.py", line 226, in train
    result = self.step()
  File "/zhome/b8/a/122402/VAE-protein/vae_env/lib/python3.8/site-packages/ray/tune/function_runner.py", line 366, in step
    self._report_thread_runner_error(block=True)
  File "/zhome/b8/a/122402/VAE-protein/vae_env/lib/python3.8/site-packages/ray/tune/function_runner.py", line 512, in _report_thread_runner_error
    raise TuneError(
ray.tune.error.TuneError: Trial raised an exception. Traceback:
[36mray::ImplicitFunc.train_buffered()[39m (pid=25266, ip=10.66.20.9)
  File "/zhome/b8/a/122402/VAE-protein/vae_env/lib/python3.8/site-packages/ray/tune/function_runner.py", line 248, in run
    self._entrypoint()
  File "/zhome/b8/a/122402/VAE-protein/vae_env/lib/python3.8/site-packages/ray/tune/function_runner.py", line 315, in entrypoint
    return self._trainable_func(self.config, self._status_reporter,
  File "/zhome/b8/a/122402/VAE-protein/vae_env/lib/python3.8/site-packages/ray/tune/function_runner.py", line 576, in _trainable_func
    output = fn()
  File "gridsearch_ray_tune.py", line 73, in train_func
    elbos, _, _ = vae.loss(x_hat_eval, eval_batch, alpha_warm_up =alpha_warm_up[k])
  File "/zhome/b8/a/122402/VAE-protein/Variational_proteins/HVAE.py", line 176, in loss
    RL = -(x_hat*true_x).sum(-1).sum(-1)
RuntimeError: CUDA out of memory. Tried to allocate 108.00 MiB (GPU 0; 31.75 GiB total capacity; 1.20 GiB already allocated; 109.00 MiB free; 1.26 GiB reserved in total by PyTorch)

