/zhome/45/c/127804/02460/python384/lib/python3.8/site-packages/ray/autoscaler/_private/cli_logger.py:57: FutureWarning: Not all Ray CLI dependencies were found. In Ray 1.4+, the Ray CLI, autoscaler, and dashboard will only be usable via `pip install 'ray[default]'`. Please update your install command.
  warnings.warn(
2021-05-01 15:17:31,752	INFO services.py:1267 -- View the Ray dashboard at [1m[32mhttp://127.0.0.1:8265[39m[22m
2021-05-01 15:17:42,149	WARNING function_runner.py:544 -- Function checkpointing is disabled. This may result in unexpected behavior when using checkpointing features or certain schedulers. To enable, set the train function arguments to be `func(config, checkpoint_dir=None)`.
[2m[36m(pid=9175)[0m 2021-05-01 15:18:08,569	WARNING __init__.py:20 -- tune.track.log is now deprecated. Use `tune.report` instead. This warning will throw an error in a future version of Ray.
2021-05-01 15:33:33,525	INFO logger.py:688 -- Removed the following hyperparameter values when logging to tensorboard: {'config/layers': (256, 256), 'config/latents': (4, 4)}
[2m[36m(pid=9174)[0m 2021-05-01 15:33:43,899	WARNING __init__.py:20 -- tune.track.log is now deprecated. Use `tune.report` instead. This warning will throw an error in a future version of Ray.
2021-05-01 15:48:58,697	INFO logger.py:688 -- Removed the following hyperparameter values when logging to tensorboard: {'config/layers': (256, 256), 'config/latents': (4, 8)}
[2m[36m(pid=9172)[0m 2021-05-01 15:49:08,676	WARNING __init__.py:20 -- tune.track.log is now deprecated. Use `tune.report` instead. This warning will throw an error in a future version of Ray.
2021-05-01 16:04:10,324	INFO logger.py:688 -- Removed the following hyperparameter values when logging to tensorboard: {'config/layers': (256, 256), 'config/latents': (4, 16)}
[2m[36m(pid=9169)[0m 2021-05-01 16:04:20,249	WARNING __init__.py:20 -- tune.track.log is now deprecated. Use `tune.report` instead. This warning will throw an error in a future version of Ray.
2021-05-01 16:19:18,129	INFO logger.py:688 -- Removed the following hyperparameter values when logging to tensorboard: {'config/layers': (256, 256), 'config/latents': (8, 8)}
[2m[36m(pid=9167)[0m 2021-05-01 16:19:27,996	WARNING __init__.py:20 -- tune.track.log is now deprecated. Use `tune.report` instead. This warning will throw an error in a future version of Ray.
2021-05-01 16:34:21,249	INFO logger.py:688 -- Removed the following hyperparameter values when logging to tensorboard: {'config/layers': (256, 256), 'config/latents': (8, 16)}
[2m[36m(pid=9166)[0m 2021-05-01 16:34:31,051	WARNING __init__.py:20 -- tune.track.log is now deprecated. Use `tune.report` instead. This warning will throw an error in a future version of Ray.
2021-05-01 16:49:08,217	INFO logger.py:688 -- Removed the following hyperparameter values when logging to tensorboard: {'config/layers': (256, 256), 'config/latents': (16, 16)}
[2m[36m(pid=9164)[0m 2021-05-01 16:49:17,954	WARNING __init__.py:20 -- tune.track.log is now deprecated. Use `tune.report` instead. This warning will throw an error in a future version of Ray.
2021-05-01 17:03:52,462	INFO logger.py:688 -- Removed the following hyperparameter values when logging to tensorboard: {'config/layers': (256, 512), 'config/latents': (4, 4)}
[2m[36m(pid=9162)[0m 2021-05-01 17:04:02,102	WARNING __init__.py:20 -- tune.track.log is now deprecated. Use `tune.report` instead. This warning will throw an error in a future version of Ray.
2021-05-01 17:18:27,615	INFO logger.py:688 -- Removed the following hyperparameter values when logging to tensorboard: {'config/layers': (256, 512), 'config/latents': (4, 8)}
[2m[36m(pid=9160)[0m 2021-05-01 17:18:37,099	WARNING __init__.py:20 -- tune.track.log is now deprecated. Use `tune.report` instead. This warning will throw an error in a future version of Ray.
2021-05-01 17:32:58,481	INFO logger.py:688 -- Removed the following hyperparameter values when logging to tensorboard: {'config/layers': (256, 512), 'config/latents': (4, 16)}
[2m[36m(pid=9161)[0m 2021-05-01 17:33:07,987	WARNING __init__.py:20 -- tune.track.log is now deprecated. Use `tune.report` instead. This warning will throw an error in a future version of Ray.
2021-05-01 17:47:22,084	INFO logger.py:688 -- Removed the following hyperparameter values when logging to tensorboard: {'config/layers': (256, 512), 'config/latents': (8, 8)}
[2m[36m(pid=9159)[0m 2021-05-01 17:47:31,626	WARNING __init__.py:20 -- tune.track.log is now deprecated. Use `tune.report` instead. This warning will throw an error in a future version of Ray.
2021-05-01 18:01:46,931	INFO logger.py:688 -- Removed the following hyperparameter values when logging to tensorboard: {'config/layers': (256, 512), 'config/latents': (8, 16)}
[2m[36m(pid=9158)[0m 2021-05-01 18:01:56,600	WARNING __init__.py:20 -- tune.track.log is now deprecated. Use `tune.report` instead. This warning will throw an error in a future version of Ray.
2021-05-01 18:15:58,824	INFO logger.py:688 -- Removed the following hyperparameter values when logging to tensorboard: {'config/layers': (256, 512), 'config/latents': (16, 16)}
[2m[36m(pid=9157)[0m 2021-05-01 18:16:08,201	WARNING __init__.py:20 -- tune.track.log is now deprecated. Use `tune.report` instead. This warning will throw an error in a future version of Ray.
2021-05-01 18:30:56,784	INFO logger.py:688 -- Removed the following hyperparameter values when logging to tensorboard: {'config/layers': (512, 512), 'config/latents': (4, 4)}
[2m[36m(pid=9154)[0m 2021-05-01 18:31:06,074	WARNING __init__.py:20 -- tune.track.log is now deprecated. Use `tune.report` instead. This warning will throw an error in a future version of Ray.
2021-05-01 18:45:44,385	INFO logger.py:688 -- Removed the following hyperparameter values when logging to tensorboard: {'config/layers': (512, 512), 'config/latents': (4, 8)}
[2m[36m(pid=9156)[0m 2021-05-01 18:45:53,645	WARNING __init__.py:20 -- tune.track.log is now deprecated. Use `tune.report` instead. This warning will throw an error in a future version of Ray.
2021-05-01 19:00:36,444	INFO logger.py:688 -- Removed the following hyperparameter values when logging to tensorboard: {'config/layers': (512, 512), 'config/latents': (4, 16)}
[2m[36m(pid=9153)[0m 2021-05-01 19:00:45,642	WARNING __init__.py:20 -- tune.track.log is now deprecated. Use `tune.report` instead. This warning will throw an error in a future version of Ray.
2021-05-01 19:15:10,710	INFO logger.py:688 -- Removed the following hyperparameter values when logging to tensorboard: {'config/layers': (512, 512), 'config/latents': (8, 8)}
[2m[36m(pid=9152)[0m 2021-05-01 19:15:19,811	WARNING __init__.py:20 -- tune.track.log is now deprecated. Use `tune.report` instead. This warning will throw an error in a future version of Ray.
2021-05-01 19:29:44,375	INFO logger.py:688 -- Removed the following hyperparameter values when logging to tensorboard: {'config/layers': (512, 512), 'config/latents': (8, 16)}
[2m[36m(pid=9151)[0m 2021-05-01 19:29:54,719	WARNING __init__.py:20 -- tune.track.log is now deprecated. Use `tune.report` instead. This warning will throw an error in a future version of Ray.
2021-05-01 19:44:08,383	INFO logger.py:688 -- Removed the following hyperparameter values when logging to tensorboard: {'config/layers': (512, 512), 'config/latents': (16, 16)}
[2m[36m(pid=9150)[0m 2021-05-01 19:44:17,557	WARNING __init__.py:20 -- tune.track.log is now deprecated. Use `tune.report` instead. This warning will throw an error in a future version of Ray.
2021-05-01 19:58:14,437	INFO logger.py:688 -- Removed the following hyperparameter values when logging to tensorboard: {'config/layers': (256, 256, 256), 'config/latents': (4, 4, 4)}
[2m[36m(pid=9149)[0m 2021-05-01 19:58:23,649	WARNING __init__.py:20 -- tune.track.log is now deprecated. Use `tune.report` instead. This warning will throw an error in a future version of Ray.
[2m[36m(pid=9149)[0m 2021-05-01 20:10:34,371	ERROR function_runner.py:254 -- Runner Thread raised error.
[2m[36m(pid=9149)[0m Traceback (most recent call last):
[2m[36m(pid=9149)[0m   File "/zhome/45/c/127804/02460/python384/lib/python3.8/site-packages/ray/tune/function_runner.py", line 248, in run
[2m[36m(pid=9149)[0m     self._entrypoint()
[2m[36m(pid=9149)[0m   File "/zhome/45/c/127804/02460/python384/lib/python3.8/site-packages/ray/tune/function_runner.py", line 315, in entrypoint
[2m[36m(pid=9149)[0m     return self._trainable_func(self.config, self._status_reporter,
[2m[36m(pid=9149)[0m   File "/zhome/45/c/127804/02460/python384/lib/python3.8/site-packages/ray/tune/function_runner.py", line 580, in _trainable_func
[2m[36m(pid=9149)[0m     output = fn()
[2m[36m(pid=9149)[0m   File "grid_search_warm_up.py", line 94, in train_func
[2m[36m(pid=9149)[0m     loss, rl, kl      = vae.loss(x_hat, batch,p_mu,p_logvar,d_mu,d_logvar,alpha_warm_up =alpha_warm_up[k])
[2m[36m(pid=9149)[0m   File "/zhome/45/c/127804/02460/Variational_proteins/HVAE_v2.py", line 183, in loss
[2m[36m(pid=9149)[0m     p = Normal(p_mu[i], p_logvar[i].mul(1/2).exp())
[2m[36m(pid=9149)[0m   File "/zhome/45/c/127804/02460/python384/lib/python3.8/site-packages/torch/distributions/normal.py", line 50, in __init__
[2m[36m(pid=9149)[0m     super(Normal, self).__init__(batch_shape, validate_args=validate_args)
[2m[36m(pid=9149)[0m   File "/zhome/45/c/127804/02460/python384/lib/python3.8/site-packages/torch/distributions/distribution.py", line 53, in __init__
[2m[36m(pid=9149)[0m     raise ValueError("The parameter {} has invalid values".format(param))
[2m[36m(pid=9149)[0m ValueError: The parameter loc has invalid values
[2m[36m(pid=9149)[0m Exception in thread Thread-2:
[2m[36m(pid=9149)[0m Traceback (most recent call last):
[2m[36m(pid=9149)[0m   File "/appl/python/3.8.4/lib/python3.8/threading.py", line 932, in _bootstrap_inner
[2m[36m(pid=9149)[0m     self.run()
[2m[36m(pid=9149)[0m   File "/zhome/45/c/127804/02460/python384/lib/python3.8/site-packages/ray/tune/function_runner.py", line 267, in run
[2m[36m(pid=9149)[0m     raise e
[2m[36m(pid=9149)[0m   File "/zhome/45/c/127804/02460/python384/lib/python3.8/site-packages/ray/tune/function_runner.py", line 248, in run
[2m[36m(pid=9149)[0m     self._entrypoint()
[2m[36m(pid=9149)[0m   File "/zhome/45/c/127804/02460/python384/lib/python3.8/site-packages/ray/tune/function_runner.py", line 315, in entrypoint
[2m[36m(pid=9149)[0m     return self._trainable_func(self.config, self._status_reporter,
[2m[36m(pid=9149)[0m   File "/zhome/45/c/127804/02460/python384/lib/python3.8/site-packages/ray/tune/function_runner.py", line 580, in _trainable_func
[2m[36m(pid=9149)[0m     output = fn()
[2m[36m(pid=9149)[0m   File "grid_search_warm_up.py", line 94, in train_func
[2m[36m(pid=9149)[0m     loss, rl, kl      = vae.loss(x_hat, batch,p_mu,p_logvar,d_mu,d_logvar,alpha_warm_up =alpha_warm_up[k])
[2m[36m(pid=9149)[0m   File "/zhome/45/c/127804/02460/Variational_proteins/HVAE_v2.py", line 183, in loss
[2m[36m(pid=9149)[0m     p = Normal(p_mu[i], p_logvar[i].mul(1/2).exp())
[2m[36m(pid=9149)[0m   File "/zhome/45/c/127804/02460/python384/lib/python3.8/site-packages/torch/distributions/normal.py", line 50, in __init__
[2m[36m(pid=9149)[0m     super(Normal, self).__init__(batch_shape, validate_args=validate_args)
[2m[36m(pid=9149)[0m   File "/zhome/45/c/127804/02460/python384/lib/python3.8/site-packages/torch/distributions/distribution.py", line 53, in __init__
[2m[36m(pid=9149)[0m     raise ValueError("The parameter {} has invalid values".format(param))
[2m[36m(pid=9149)[0m ValueError: The parameter loc has invalid values
2021-05-01 20:10:34,521	ERROR trial_runner.py:732 -- Trial train_func_9c1c7_00019: Error processing event.
Traceback (most recent call last):
  File "/zhome/45/c/127804/02460/python384/lib/python3.8/site-packages/ray/tune/trial_runner.py", line 702, in _process_trial
    results = self.trial_executor.fetch_result(trial)
  File "/zhome/45/c/127804/02460/python384/lib/python3.8/site-packages/ray/tune/ray_trial_executor.py", line 686, in fetch_result
    result = ray.get(trial_future[0], timeout=DEFAULT_GET_TIMEOUT)
  File "/zhome/45/c/127804/02460/python384/lib/python3.8/site-packages/ray/_private/client_mode_hook.py", line 47, in wrapper
    return func(*args, **kwargs)
  File "/zhome/45/c/127804/02460/python384/lib/python3.8/site-packages/ray/worker.py", line 1481, in get
    raise value.as_instanceof_cause()
ray.exceptions.RayTaskError(TuneError): [36mray::ImplicitFunc.train_buffered()[39m (pid=9149, ip=10.66.20.3)
  File "python/ray/_raylet.pyx", line 505, in ray._raylet.execute_task
  File "python/ray/_raylet.pyx", line 449, in ray._raylet.execute_task.function_executor
  File "/zhome/45/c/127804/02460/python384/lib/python3.8/site-packages/ray/_private/function_manager.py", line 556, in actor_method_executor
    return method(__ray_actor, *args, **kwargs)
  File "/zhome/45/c/127804/02460/python384/lib/python3.8/site-packages/ray/tune/trainable.py", line 173, in train_buffered
    result = self.train()
  File "/zhome/45/c/127804/02460/python384/lib/python3.8/site-packages/ray/tune/trainable.py", line 232, in train
    result = self.step()
  File "/zhome/45/c/127804/02460/python384/lib/python3.8/site-packages/ray/tune/function_runner.py", line 366, in step
    self._report_thread_runner_error(block=True)
  File "/zhome/45/c/127804/02460/python384/lib/python3.8/site-packages/ray/tune/function_runner.py", line 512, in _report_thread_runner_error
    raise TuneError(
ray.tune.error.TuneError: Trial raised an exception. Traceback:
[36mray::ImplicitFunc.train_buffered()[39m (pid=9149, ip=10.66.20.3)
  File "/zhome/45/c/127804/02460/python384/lib/python3.8/site-packages/ray/tune/function_runner.py", line 248, in run
    self._entrypoint()
  File "/zhome/45/c/127804/02460/python384/lib/python3.8/site-packages/ray/tune/function_runner.py", line 315, in entrypoint
    return self._trainable_func(self.config, self._status_reporter,
  File "/zhome/45/c/127804/02460/python384/lib/python3.8/site-packages/ray/tune/function_runner.py", line 580, in _trainable_func
    output = fn()
  File "grid_search_warm_up.py", line 94, in train_func
    loss, rl, kl      = vae.loss(x_hat, batch,p_mu,p_logvar,d_mu,d_logvar,alpha_warm_up =alpha_warm_up[k])
  File "/zhome/45/c/127804/02460/Variational_proteins/HVAE_v2.py", line 183, in loss
    p = Normal(p_mu[i], p_logvar[i].mul(1/2).exp())
  File "/zhome/45/c/127804/02460/python384/lib/python3.8/site-packages/torch/distributions/normal.py", line 50, in __init__
    super(Normal, self).__init__(batch_shape, validate_args=validate_args)
  File "/zhome/45/c/127804/02460/python384/lib/python3.8/site-packages/torch/distributions/distribution.py", line 53, in __init__
    raise ValueError("The parameter {} has invalid values".format(param))
ValueError: The parameter loc has invalid values
2021-05-01 20:10:34,532	INFO logger.py:688 -- Removed the following hyperparameter values when logging to tensorboard: {'config/layers': (256, 256, 256), 'config/latents': (4, 4, 8)}
[2m[36m(pid=9148)[0m 2021-05-01 20:10:43,632	WARNING __init__.py:20 -- tune.track.log is now deprecated. Use `tune.report` instead. This warning will throw an error in a future version of Ray.
[2m[36m(pid=9148)[0m 2021-05-01 20:11:00,041	ERROR function_runner.py:254 -- Runner Thread raised error.
[2m[36m(pid=9148)[0m Traceback (most recent call last):
[2m[36m(pid=9148)[0m   File "/zhome/45/c/127804/02460/python384/lib/python3.8/site-packages/ray/tune/function_runner.py", line 248, in run
[2m[36m(pid=9148)[0m     self._entrypoint()
[2m[36m(pid=9148)[0m   File "/zhome/45/c/127804/02460/python384/lib/python3.8/site-packages/ray/tune/function_runner.py", line 315, in entrypoint
[2m[36m(pid=9148)[0m     return self._trainable_func(self.config, self._status_reporter,
[2m[36m(pid=9148)[0m   File "/zhome/45/c/127804/02460/python384/lib/python3.8/site-packages/ray/tune/function_runner.py", line 580, in _trainable_func
[2m[36m(pid=9148)[0m     output = fn()
[2m[36m(pid=9148)[0m   File "grid_search_warm_up.py", line 94, in train_func
[2m[36m(pid=9148)[0m     loss, rl, kl      = vae.loss(x_hat, batch,p_mu,p_logvar,d_mu,d_logvar,alpha_warm_up =alpha_warm_up[k])
[2m[36m(pid=9148)[0m   File "/zhome/45/c/127804/02460/Variational_proteins/HVAE_v2.py", line 183, in loss
[2m[36m(pid=9148)[0m     p = Normal(p_mu[i], p_logvar[i].mul(1/2).exp())
[2m[36m(pid=9148)[0m   File "/zhome/45/c/127804/02460/python384/lib/python3.8/site-packages/torch/distributions/normal.py", line 50, in __init__
[2m[36m(pid=9148)[0m     super(Normal, self).__init__(batch_shape, validate_args=validate_args)
[2m[36m(pid=9148)[0m   File "/zhome/45/c/127804/02460/python384/lib/python3.8/site-packages/torch/distributions/distribution.py", line 53, in __init__
[2m[36m(pid=9148)[0m     raise ValueError("The parameter {} has invalid values".format(param))
[2m[36m(pid=9148)[0m ValueError: The parameter loc has invalid values
[2m[36m(pid=9148)[0m Exception in thread Thread-2:
[2m[36m(pid=9148)[0m Traceback (most recent call last):
[2m[36m(pid=9148)[0m   File "/appl/python/3.8.4/lib/python3.8/threading.py", line 932, in _bootstrap_inner
[2m[36m(pid=9148)[0m     self.run()
[2m[36m(pid=9148)[0m   File "/zhome/45/c/127804/02460/python384/lib/python3.8/site-packages/ray/tune/function_runner.py", line 267, in run
[2m[36m(pid=9148)[0m     raise e
[2m[36m(pid=9148)[0m   File "/zhome/45/c/127804/02460/python384/lib/python3.8/site-packages/ray/tune/function_runner.py", line 248, in run
[2m[36m(pid=9148)[0m     self._entrypoint()
[2m[36m(pid=9148)[0m   File "/zhome/45/c/127804/02460/python384/lib/python3.8/site-packages/ray/tune/function_runner.py", line 315, in entrypoint
[2m[36m(pid=9148)[0m     return self._trainable_func(self.config, self._status_reporter,
[2m[36m(pid=9148)[0m   File "/zhome/45/c/127804/02460/python384/lib/python3.8/site-packages/ray/tune/function_runner.py", line 580, in _trainable_func
[2m[36m(pid=9148)[0m     output = fn()
[2m[36m(pid=9148)[0m   File "grid_search_warm_up.py", line 94, in train_func
[2m[36m(pid=9148)[0m     loss, rl, kl      = vae.loss(x_hat, batch,p_mu,p_logvar,d_mu,d_logvar,alpha_warm_up =alpha_warm_up[k])
[2m[36m(pid=9148)[0m   File "/zhome/45/c/127804/02460/Variational_proteins/HVAE_v2.py", line 183, in loss
[2m[36m(pid=9148)[0m     p = Normal(p_mu[i], p_logvar[i].mul(1/2).exp())
[2m[36m(pid=9148)[0m   File "/zhome/45/c/127804/02460/python384/lib/python3.8/site-packages/torch/distributions/normal.py", line 50, in __init__
[2m[36m(pid=9148)[0m     super(Normal, self).__init__(batch_shape, validate_args=validate_args)
[2m[36m(pid=9148)[0m   File "/zhome/45/c/127804/02460/python384/lib/python3.8/site-packages/torch/distributions/distribution.py", line 53, in __init__
[2m[36m(pid=9148)[0m     raise ValueError("The parameter {} has invalid values".format(param))
[2m[36m(pid=9148)[0m ValueError: The parameter loc has invalid values
2021-05-01 20:11:00,108	ERROR trial_runner.py:732 -- Trial train_func_9c1c7_00020: Error processing event.
Traceback (most recent call last):
  File "/zhome/45/c/127804/02460/python384/lib/python3.8/site-packages/ray/tune/trial_runner.py", line 702, in _process_trial
    results = self.trial_executor.fetch_result(trial)
  File "/zhome/45/c/127804/02460/python384/lib/python3.8/site-packages/ray/tune/ray_trial_executor.py", line 686, in fetch_result
    result = ray.get(trial_future[0], timeout=DEFAULT_GET_TIMEOUT)
  File "/zhome/45/c/127804/02460/python384/lib/python3.8/site-packages/ray/_private/client_mode_hook.py", line 47, in wrapper
    return func(*args, **kwargs)
  File "/zhome/45/c/127804/02460/python384/lib/python3.8/site-packages/ray/worker.py", line 1481, in get
    raise value.as_instanceof_cause()
ray.exceptions.RayTaskError(TuneError): [36mray::ImplicitFunc.train_buffered()[39m (pid=9148, ip=10.66.20.3)
  File "python/ray/_raylet.pyx", line 505, in ray._raylet.execute_task
  File "python/ray/_raylet.pyx", line 449, in ray._raylet.execute_task.function_executor
  File "/zhome/45/c/127804/02460/python384/lib/python3.8/site-packages/ray/_private/function_manager.py", line 556, in actor_method_executor
    return method(__ray_actor, *args, **kwargs)
  File "/zhome/45/c/127804/02460/python384/lib/python3.8/site-packages/ray/tune/trainable.py", line 173, in train_buffered
    result = self.train()
  File "/zhome/45/c/127804/02460/python384/lib/python3.8/site-packages/ray/tune/trainable.py", line 232, in train
    result = self.step()
  File "/zhome/45/c/127804/02460/python384/lib/python3.8/site-packages/ray/tune/function_runner.py", line 366, in step
    self._report_thread_runner_error(block=True)
  File "/zhome/45/c/127804/02460/python384/lib/python3.8/site-packages/ray/tune/function_runner.py", line 512, in _report_thread_runner_error
    raise TuneError(
ray.tune.error.TuneError: Trial raised an exception. Traceback:
[36mray::ImplicitFunc.train_buffered()[39m (pid=9148, ip=10.66.20.3)
  File "/zhome/45/c/127804/02460/python384/lib/python3.8/site-packages/ray/tune/function_runner.py", line 248, in run
    self._entrypoint()
  File "/zhome/45/c/127804/02460/python384/lib/python3.8/site-packages/ray/tune/function_runner.py", line 315, in entrypoint
    return self._trainable_func(self.config, self._status_reporter,
  File "/zhome/45/c/127804/02460/python384/lib/python3.8/site-packages/ray/tune/function_runner.py", line 580, in _trainable_func
    output = fn()
  File "grid_search_warm_up.py", line 94, in train_func
    loss, rl, kl      = vae.loss(x_hat, batch,p_mu,p_logvar,d_mu,d_logvar,alpha_warm_up =alpha_warm_up[k])
  File "/zhome/45/c/127804/02460/Variational_proteins/HVAE_v2.py", line 183, in loss
    p = Normal(p_mu[i], p_logvar[i].mul(1/2).exp())
  File "/zhome/45/c/127804/02460/python384/lib/python3.8/site-packages/torch/distributions/normal.py", line 50, in __init__
    super(Normal, self).__init__(batch_shape, validate_args=validate_args)
  File "/zhome/45/c/127804/02460/python384/lib/python3.8/site-packages/torch/distributions/distribution.py", line 53, in __init__
    raise ValueError("The parameter {} has invalid values".format(param))
ValueError: The parameter loc has invalid values
2021-05-01 20:11:00,114	INFO logger.py:688 -- Removed the following hyperparameter values when logging to tensorboard: {'config/layers': (256, 256, 256), 'config/latents': (4, 4, 16)}
[2m[36m(pid=9143)[0m 2021-05-01 20:11:09,233	WARNING __init__.py:20 -- tune.track.log is now deprecated. Use `tune.report` instead. This warning will throw an error in a future version of Ray.
[2m[36m(pid=9143)[0m 2021-05-01 20:11:21,405	ERROR function_runner.py:254 -- Runner Thread raised error.
[2m[36m(pid=9143)[0m Traceback (most recent call last):
[2m[36m(pid=9143)[0m   File "/zhome/45/c/127804/02460/python384/lib/python3.8/site-packages/ray/tune/function_runner.py", line 248, in run
[2m[36m(pid=9143)[0m     self._entrypoint()
[2m[36m(pid=9143)[0m   File "/zhome/45/c/127804/02460/python384/lib/python3.8/site-packages/ray/tune/function_runner.py", line 315, in entrypoint
[2m[36m(pid=9143)[0m     return self._trainable_func(self.config, self._status_reporter,
[2m[36m(pid=9143)[0m   File "/zhome/45/c/127804/02460/python384/lib/python3.8/site-packages/ray/tune/function_runner.py", line 580, in _trainable_func
[2m[36m(pid=9143)[0m     output = fn()
[2m[36m(pid=9143)[0m   File "grid_search_warm_up.py", line 94, in train_func
[2m[36m(pid=9143)[0m     loss, rl, kl      = vae.loss(x_hat, batch,p_mu,p_logvar,d_mu,d_logvar,alpha_warm_up =alpha_warm_up[k])
[2m[36m(pid=9143)[0m   File "/zhome/45/c/127804/02460/Variational_proteins/HVAE_v2.py", line 183, in loss
[2m[36m(pid=9143)[0m     p = Normal(p_mu[i], p_logvar[i].mul(1/2).exp())
[2m[36m(pid=9143)[0m   File "/zhome/45/c/127804/02460/python384/lib/python3.8/site-packages/torch/distributions/normal.py", line 50, in __init__
[2m[36m(pid=9143)[0m     super(Normal, self).__init__(batch_shape, validate_args=validate_args)
[2m[36m(pid=9143)[0m   File "/zhome/45/c/127804/02460/python384/lib/python3.8/site-packages/torch/distributions/distribution.py", line 53, in __init__
[2m[36m(pid=9143)[0m     raise ValueError("The parameter {} has invalid values".format(param))
[2m[36m(pid=9143)[0m ValueError: The parameter loc has invalid values
[2m[36m(pid=9143)[0m Exception in thread Thread-2:
[2m[36m(pid=9143)[0m Traceback (most recent call last):
[2m[36m(pid=9143)[0m   File "/appl/python/3.8.4/lib/python3.8/threading.py", line 932, in _bootstrap_inner
[2m[36m(pid=9143)[0m     self.run()
[2m[36m(pid=9143)[0m   File "/zhome/45/c/127804/02460/python384/lib/python3.8/site-packages/ray/tune/function_runner.py", line 267, in run
[2m[36m(pid=9143)[0m     raise e
[2m[36m(pid=9143)[0m   File "/zhome/45/c/127804/02460/python384/lib/python3.8/site-packages/ray/tune/function_runner.py", line 248, in run
[2m[36m(pid=9143)[0m     self._entrypoint()
[2m[36m(pid=9143)[0m   File "/zhome/45/c/127804/02460/python384/lib/python3.8/site-packages/ray/tune/function_runner.py", line 315, in entrypoint
[2m[36m(pid=9143)[0m     return self._trainable_func(self.config, self._status_reporter,
[2m[36m(pid=9143)[0m   File "/zhome/45/c/127804/02460/python384/lib/python3.8/site-packages/ray/tune/function_runner.py", line 580, in _trainable_func
[2m[36m(pid=9143)[0m     output = fn()
[2m[36m(pid=9143)[0m   File "grid_search_warm_up.py", line 94, in train_func
[2m[36m(pid=9143)[0m     loss, rl, kl      = vae.loss(x_hat, batch,p_mu,p_logvar,d_mu,d_logvar,alpha_warm_up =alpha_warm_up[k])
[2m[36m(pid=9143)[0m   File "/zhome/45/c/127804/02460/Variational_proteins/HVAE_v2.py", line 183, in loss
[2m[36m(pid=9143)[0m     p = Normal(p_mu[i], p_logvar[i].mul(1/2).exp())
[2m[36m(pid=9143)[0m   File "/zhome/45/c/127804/02460/python384/lib/python3.8/site-packages/torch/distributions/normal.py", line 50, in __init__
[2m[36m(pid=9143)[0m     super(Normal, self).__init__(batch_shape, validate_args=validate_args)
[2m[36m(pid=9143)[0m   File "/zhome/45/c/127804/02460/python384/lib/python3.8/site-packages/torch/distributions/distribution.py", line 53, in __init__
[2m[36m(pid=9143)[0m     raise ValueError("The parameter {} has invalid values".format(param))
[2m[36m(pid=9143)[0m ValueError: The parameter loc has invalid values
2021-05-01 20:11:21,507	ERROR trial_runner.py:732 -- Trial train_func_9c1c7_00021: Error processing event.
Traceback (most recent call last):
  File "/zhome/45/c/127804/02460/python384/lib/python3.8/site-packages/ray/tune/trial_runner.py", line 702, in _process_trial
    results = self.trial_executor.fetch_result(trial)
  File "/zhome/45/c/127804/02460/python384/lib/python3.8/site-packages/ray/tune/ray_trial_executor.py", line 686, in fetch_result
    result = ray.get(trial_future[0], timeout=DEFAULT_GET_TIMEOUT)
  File "/zhome/45/c/127804/02460/python384/lib/python3.8/site-packages/ray/_private/client_mode_hook.py", line 47, in wrapper
    return func(*args, **kwargs)
  File "/zhome/45/c/127804/02460/python384/lib/python3.8/site-packages/ray/worker.py", line 1481, in get
    raise value.as_instanceof_cause()
ray.exceptions.RayTaskError(TuneError): [36mray::ImplicitFunc.train_buffered()[39m (pid=9143, ip=10.66.20.3)
  File "python/ray/_raylet.pyx", line 505, in ray._raylet.execute_task
  File "python/ray/_raylet.pyx", line 449, in ray._raylet.execute_task.function_executor
  File "/zhome/45/c/127804/02460/python384/lib/python3.8/site-packages/ray/_private/function_manager.py", line 556, in actor_method_executor
    return method(__ray_actor, *args, **kwargs)
  File "/zhome/45/c/127804/02460/python384/lib/python3.8/site-packages/ray/tune/trainable.py", line 173, in train_buffered
    result = self.train()
  File "/zhome/45/c/127804/02460/python384/lib/python3.8/site-packages/ray/tune/trainable.py", line 232, in train
    result = self.step()
  File "/zhome/45/c/127804/02460/python384/lib/python3.8/site-packages/ray/tune/function_runner.py", line 366, in step
    self._report_thread_runner_error(block=True)
  File "/zhome/45/c/127804/02460/python384/lib/python3.8/site-packages/ray/tune/function_runner.py", line 512, in _report_thread_runner_error
    raise TuneError(
ray.tune.error.TuneError: Trial raised an exception. Traceback:
[36mray::ImplicitFunc.train_buffered()[39m (pid=9143, ip=10.66.20.3)
  File "/zhome/45/c/127804/02460/python384/lib/python3.8/site-packages/ray/tune/function_runner.py", line 248, in run
    self._entrypoint()
  File "/zhome/45/c/127804/02460/python384/lib/python3.8/site-packages/ray/tune/function_runner.py", line 315, in entrypoint
    return self._trainable_func(self.config, self._status_reporter,
  File "/zhome/45/c/127804/02460/python384/lib/python3.8/site-packages/ray/tune/function_runner.py", line 580, in _trainable_func
    output = fn()
  File "grid_search_warm_up.py", line 94, in train_func
    loss, rl, kl      = vae.loss(x_hat, batch,p_mu,p_logvar,d_mu,d_logvar,alpha_warm_up =alpha_warm_up[k])
  File "/zhome/45/c/127804/02460/Variational_proteins/HVAE_v2.py", line 183, in loss
    p = Normal(p_mu[i], p_logvar[i].mul(1/2).exp())
  File "/zhome/45/c/127804/02460/python384/lib/python3.8/site-packages/torch/distributions/normal.py", line 50, in __init__
    super(Normal, self).__init__(batch_shape, validate_args=validate_args)
  File "/zhome/45/c/127804/02460/python384/lib/python3.8/site-packages/torch/distributions/distribution.py", line 53, in __init__
    raise ValueError("The parameter {} has invalid values".format(param))
ValueError: The parameter loc has invalid values
2021-05-01 20:11:21,514	INFO logger.py:688 -- Removed the following hyperparameter values when logging to tensorboard: {'config/layers': (256, 256, 256), 'config/latents': (4, 8, 8)}
[2m[36m(pid=9141)[0m 2021-05-01 20:11:30,412	WARNING __init__.py:20 -- tune.track.log is now deprecated. Use `tune.report` instead. This warning will throw an error in a future version of Ray.
2021-05-01 20:25:03,086	INFO logger.py:688 -- Removed the following hyperparameter values when logging to tensorboard: {'config/layers': (256, 256, 256), 'config/latents': (4, 8, 16)}
[2m[36m(pid=9142)[0m 2021-05-01 20:25:11,952	WARNING __init__.py:20 -- tune.track.log is now deprecated. Use `tune.report` instead. This warning will throw an error in a future version of Ray.
2021-05-01 20:38:47,470	INFO logger.py:688 -- Removed the following hyperparameter values when logging to tensorboard: {'config/layers': (256, 256, 256), 'config/latents': (4, 16, 16)}
[2m[33m(raylet)[0m /zhome/45/c/127804/02460/python384/lib/python3.8/site-packages/ray/autoscaler/_private/cli_logger.py:57: FutureWarning: Not all Ray CLI dependencies were found. In Ray 1.4+, the Ray CLI, autoscaler, and dashboard will only be usable via `pip install 'ray[default]'`. Please update your install command.
[2m[33m(raylet)[0m   warnings.warn(
[2m[36m(pid=28612)[0m 2021-05-01 20:38:57,140	WARNING __init__.py:20 -- tune.track.log is now deprecated. Use `tune.report` instead. This warning will throw an error in a future version of Ray.
[2m[36m(pid=28612)[0m 2021-05-01 20:40:13,625	ERROR function_runner.py:254 -- Runner Thread raised error.
[2m[36m(pid=28612)[0m Traceback (most recent call last):
[2m[36m(pid=28612)[0m   File "/zhome/45/c/127804/02460/python384/lib/python3.8/site-packages/ray/tune/function_runner.py", line 248, in run
[2m[36m(pid=28612)[0m     self._entrypoint()
[2m[36m(pid=28612)[0m   File "/zhome/45/c/127804/02460/python384/lib/python3.8/site-packages/ray/tune/function_runner.py", line 315, in entrypoint
[2m[36m(pid=28612)[0m     return self._trainable_func(self.config, self._status_reporter,
[2m[36m(pid=28612)[0m   File "/zhome/45/c/127804/02460/python384/lib/python3.8/site-packages/ray/tune/function_runner.py", line 580, in _trainable_func
[2m[36m(pid=28612)[0m     output = fn()
[2m[36m(pid=28612)[0m   File "grid_search_warm_up.py", line 94, in train_func
[2m[36m(pid=28612)[0m     loss, rl, kl      = vae.loss(x_hat, batch,p_mu,p_logvar,d_mu,d_logvar,alpha_warm_up =alpha_warm_up[k])
[2m[36m(pid=28612)[0m   File "/zhome/45/c/127804/02460/Variational_proteins/HVAE_v2.py", line 183, in loss
[2m[36m(pid=28612)[0m     p = Normal(p_mu[i], p_logvar[i].mul(1/2).exp())
[2m[36m(pid=28612)[0m   File "/zhome/45/c/127804/02460/python384/lib/python3.8/site-packages/torch/distributions/normal.py", line 50, in __init__
[2m[36m(pid=28612)[0m     super(Normal, self).__init__(batch_shape, validate_args=validate_args)
[2m[36m(pid=28612)[0m   File "/zhome/45/c/127804/02460/python384/lib/python3.8/site-packages/torch/distributions/distribution.py", line 53, in __init__
[2m[36m(pid=28612)[0m     raise ValueError("The parameter {} has invalid values".format(param))
[2m[36m(pid=28612)[0m ValueError: The parameter loc has invalid values
[2m[36m(pid=28612)[0m Exception in thread Thread-2:
[2m[36m(pid=28612)[0m Traceback (most recent call last):
[2m[36m(pid=28612)[0m   File "/appl/python/3.8.4/lib/python3.8/threading.py", line 932, in _bootstrap_inner
[2m[36m(pid=28612)[0m     self.run()
[2m[36m(pid=28612)[0m   File "/zhome/45/c/127804/02460/python384/lib/python3.8/site-packages/ray/tune/function_runner.py", line 267, in run
[2m[36m(pid=28612)[0m     raise e
[2m[36m(pid=28612)[0m   File "/zhome/45/c/127804/02460/python384/lib/python3.8/site-packages/ray/tune/function_runner.py", line 248, in run
[2m[36m(pid=28612)[0m     self._entrypoint()
[2m[36m(pid=28612)[0m   File "/zhome/45/c/127804/02460/python384/lib/python3.8/site-packages/ray/tune/function_runner.py", line 315, in entrypoint
[2m[36m(pid=28612)[0m     return self._trainable_func(self.config, self._status_reporter,
[2m[36m(pid=28612)[0m   File "/zhome/45/c/127804/02460/python384/lib/python3.8/site-packages/ray/tune/function_runner.py", line 580, in _trainable_func
[2m[36m(pid=28612)[0m     output = fn()
[2m[36m(pid=28612)[0m   File "grid_search_warm_up.py", line 94, in train_func
[2m[36m(pid=28612)[0m     loss, rl, kl      = vae.loss(x_hat, batch,p_mu,p_logvar,d_mu,d_logvar,alpha_warm_up =alpha_warm_up[k])
[2m[36m(pid=28612)[0m   File "/zhome/45/c/127804/02460/Variational_proteins/HVAE_v2.py", line 183, in loss
[2m[36m(pid=28612)[0m     p = Normal(p_mu[i], p_logvar[i].mul(1/2).exp())
[2m[36m(pid=28612)[0m   File "/zhome/45/c/127804/02460/python384/lib/python3.8/site-packages/torch/distributions/normal.py", line 50, in __init__
[2m[36m(pid=28612)[0m     super(Normal, self).__init__(batch_shape, validate_args=validate_args)
[2m[36m(pid=28612)[0m   File "/zhome/45/c/127804/02460/python384/lib/python3.8/site-packages/torch/distributions/distribution.py", line 53, in __init__
[2m[36m(pid=28612)[0m     raise ValueError("The parameter {} has invalid values".format(param))
[2m[36m(pid=28612)[0m ValueError: The parameter loc has invalid values
2021-05-01 20:40:13,762	ERROR trial_runner.py:732 -- Trial train_func_9c1c7_00024: Error processing event.
Traceback (most recent call last):
  File "/zhome/45/c/127804/02460/python384/lib/python3.8/site-packages/ray/tune/trial_runner.py", line 702, in _process_trial
    results = self.trial_executor.fetch_result(trial)
  File "/zhome/45/c/127804/02460/python384/lib/python3.8/site-packages/ray/tune/ray_trial_executor.py", line 686, in fetch_result
    result = ray.get(trial_future[0], timeout=DEFAULT_GET_TIMEOUT)
  File "/zhome/45/c/127804/02460/python384/lib/python3.8/site-packages/ray/_private/client_mode_hook.py", line 47, in wrapper
    return func(*args, **kwargs)
  File "/zhome/45/c/127804/02460/python384/lib/python3.8/site-packages/ray/worker.py", line 1481, in get
    raise value.as_instanceof_cause()
ray.exceptions.RayTaskError(TuneError): [36mray::ImplicitFunc.train_buffered()[39m (pid=28612, ip=10.66.20.3)
  File "python/ray/_raylet.pyx", line 505, in ray._raylet.execute_task
  File "python/ray/_raylet.pyx", line 449, in ray._raylet.execute_task.function_executor
  File "/zhome/45/c/127804/02460/python384/lib/python3.8/site-packages/ray/_private/function_manager.py", line 556, in actor_method_executor
    return method(__ray_actor, *args, **kwargs)
  File "/zhome/45/c/127804/02460/python384/lib/python3.8/site-packages/ray/tune/trainable.py", line 173, in train_buffered
    result = self.train()
  File "/zhome/45/c/127804/02460/python384/lib/python3.8/site-packages/ray/tune/trainable.py", line 232, in train
    result = self.step()
  File "/zhome/45/c/127804/02460/python384/lib/python3.8/site-packages/ray/tune/function_runner.py", line 366, in step
    self._report_thread_runner_error(block=True)
  File "/zhome/45/c/127804/02460/python384/lib/python3.8/site-packages/ray/tune/function_runner.py", line 512, in _report_thread_runner_error
    raise TuneError(
ray.tune.error.TuneError: Trial raised an exception. Traceback:
[36mray::ImplicitFunc.train_buffered()[39m (pid=28612, ip=10.66.20.3)
  File "/zhome/45/c/127804/02460/python384/lib/python3.8/site-packages/ray/tune/function_runner.py", line 248, in run
    self._entrypoint()
  File "/zhome/45/c/127804/02460/python384/lib/python3.8/site-packages/ray/tune/function_runner.py", line 315, in entrypoint
    return self._trainable_func(self.config, self._status_reporter,
  File "/zhome/45/c/127804/02460/python384/lib/python3.8/site-packages/ray/tune/function_runner.py", line 580, in _trainable_func
    output = fn()
  File "grid_search_warm_up.py", line 94, in train_func
    loss, rl, kl      = vae.loss(x_hat, batch,p_mu,p_logvar,d_mu,d_logvar,alpha_warm_up =alpha_warm_up[k])
  File "/zhome/45/c/127804/02460/Variational_proteins/HVAE_v2.py", line 183, in loss
    p = Normal(p_mu[i], p_logvar[i].mul(1/2).exp())
  File "/zhome/45/c/127804/02460/python384/lib/python3.8/site-packages/torch/distributions/normal.py", line 50, in __init__
    super(Normal, self).__init__(batch_shape, validate_args=validate_args)
  File "/zhome/45/c/127804/02460/python384/lib/python3.8/site-packages/torch/distributions/distribution.py", line 53, in __init__
    raise ValueError("The parameter {} has invalid values".format(param))
ValueError: The parameter loc has invalid values
2021-05-01 20:40:13,767	INFO logger.py:688 -- Removed the following hyperparameter values when logging to tensorboard: {'config/layers': (256, 256, 256), 'config/latents': (8, 8, 8)}
[2m[33m(raylet)[0m /zhome/45/c/127804/02460/python384/lib/python3.8/site-packages/ray/autoscaler/_private/cli_logger.py:57: FutureWarning: Not all Ray CLI dependencies were found. In Ray 1.4+, the Ray CLI, autoscaler, and dashboard will only be usable via `pip install 'ray[default]'`. Please update your install command.
[2m[33m(raylet)[0m   warnings.warn(
[2m[36m(pid=28727)[0m 2021-05-01 20:40:23,313	WARNING __init__.py:20 -- tune.track.log is now deprecated. Use `tune.report` instead. This warning will throw an error in a future version of Ray.
2021-05-01 20:53:58,956	INFO logger.py:688 -- Removed the following hyperparameter values when logging to tensorboard: {'config/layers': (256, 256, 256), 'config/latents': (8, 8, 16)}
[2m[33m(raylet)[0m /zhome/45/c/127804/02460/python384/lib/python3.8/site-packages/ray/autoscaler/_private/cli_logger.py:57: FutureWarning: Not all Ray CLI dependencies were found. In Ray 1.4+, the Ray CLI, autoscaler, and dashboard will only be usable via `pip install 'ray[default]'`. Please update your install command.
[2m[33m(raylet)[0m   warnings.warn(
[2m[36m(pid=29550)[0m 2021-05-01 20:54:09,960	WARNING __init__.py:20 -- tune.track.log is now deprecated. Use `tune.report` instead. This warning will throw an error in a future version of Ray.
2021-05-01 21:07:46,810	INFO logger.py:688 -- Removed the following hyperparameter values when logging to tensorboard: {'config/layers': (256, 256, 256), 'config/latents': (8, 16, 16)}
[2m[33m(raylet)[0m /zhome/45/c/127804/02460/python384/lib/python3.8/site-packages/ray/autoscaler/_private/cli_logger.py:57: FutureWarning: Not all Ray CLI dependencies were found. In Ray 1.4+, the Ray CLI, autoscaler, and dashboard will only be usable via `pip install 'ray[default]'`. Please update your install command.
[2m[33m(raylet)[0m   warnings.warn(
[2m[36m(pid=30407)[0m 2021-05-01 21:07:56,375	WARNING __init__.py:20 -- tune.track.log is now deprecated. Use `tune.report` instead. This warning will throw an error in a future version of Ray.
2021-05-01 21:21:23,471	INFO logger.py:688 -- Removed the following hyperparameter values when logging to tensorboard: {'config/layers': (256, 256, 256), 'config/latents': (16, 16, 16)}
[2m[33m(raylet)[0m /zhome/45/c/127804/02460/python384/lib/python3.8/site-packages/ray/autoscaler/_private/cli_logger.py:57: FutureWarning: Not all Ray CLI dependencies were found. In Ray 1.4+, the Ray CLI, autoscaler, and dashboard will only be usable via `pip install 'ray[default]'`. Please update your install command.
[2m[33m(raylet)[0m   warnings.warn(
[2m[36m(pid=31259)[0m 2021-05-01 21:21:33,021	WARNING __init__.py:20 -- tune.track.log is now deprecated. Use `tune.report` instead. This warning will throw an error in a future version of Ray.
2021-05-01 21:35:06,931	INFO logger.py:688 -- Removed the following hyperparameter values when logging to tensorboard: {'config/layers': (256, 256, 512), 'config/latents': (4, 4, 4)}
[2m[33m(raylet)[0m /zhome/45/c/127804/02460/python384/lib/python3.8/site-packages/ray/autoscaler/_private/cli_logger.py:57: FutureWarning: Not all Ray CLI dependencies were found. In Ray 1.4+, the Ray CLI, autoscaler, and dashboard will only be usable via `pip install 'ray[default]'`. Please update your install command.
[2m[33m(raylet)[0m   warnings.warn(
[2m[36m(pid=32077)[0m 2021-05-01 21:35:16,571	WARNING __init__.py:20 -- tune.track.log is now deprecated. Use `tune.report` instead. This warning will throw an error in a future version of Ray.
[2m[36m(pid=32077)[0m 2021-05-01 21:43:27,178	ERROR function_runner.py:254 -- Runner Thread raised error.
[2m[36m(pid=32077)[0m Traceback (most recent call last):
[2m[36m(pid=32077)[0m   File "/zhome/45/c/127804/02460/python384/lib/python3.8/site-packages/ray/tune/function_runner.py", line 248, in run
[2m[36m(pid=32077)[0m     self._entrypoint()
[2m[36m(pid=32077)[0m   File "/zhome/45/c/127804/02460/python384/lib/python3.8/site-packages/ray/tune/function_runner.py", line 315, in entrypoint
[2m[36m(pid=32077)[0m     return self._trainable_func(self.config, self._status_reporter,
[2m[36m(pid=32077)[0m   File "/zhome/45/c/127804/02460/python384/lib/python3.8/site-packages/ray/tune/function_runner.py", line 580, in _trainable_func
[2m[36m(pid=32077)[0m     output = fn()
[2m[36m(pid=32077)[0m   File "grid_search_warm_up.py", line 94, in train_func
[2m[36m(pid=32077)[0m     loss, rl, kl      = vae.loss(x_hat, batch,p_mu,p_logvar,d_mu,d_logvar,alpha_warm_up =alpha_warm_up[k])
[2m[36m(pid=32077)[0m   File "/zhome/45/c/127804/02460/Variational_proteins/HVAE_v2.py", line 183, in loss
[2m[36m(pid=32077)[0m     p = Normal(p_mu[i], p_logvar[i].mul(1/2).exp())
[2m[36m(pid=32077)[0m   File "/zhome/45/c/127804/02460/python384/lib/python3.8/site-packages/torch/distributions/normal.py", line 50, in __init__
[2m[36m(pid=32077)[0m     super(Normal, self).__init__(batch_shape, validate_args=validate_args)
[2m[36m(pid=32077)[0m   File "/zhome/45/c/127804/02460/python384/lib/python3.8/site-packages/torch/distributions/distribution.py", line 53, in __init__
[2m[36m(pid=32077)[0m     raise ValueError("The parameter {} has invalid values".format(param))
[2m[36m(pid=32077)[0m ValueError: The parameter loc has invalid values
[2m[36m(pid=32077)[0m Exception in thread Thread-2:
[2m[36m(pid=32077)[0m Traceback (most recent call last):
[2m[36m(pid=32077)[0m   File "/appl/python/3.8.4/lib/python3.8/threading.py", line 932, in _bootstrap_inner
[2m[36m(pid=32077)[0m     self.run()
[2m[36m(pid=32077)[0m   File "/zhome/45/c/127804/02460/python384/lib/python3.8/site-packages/ray/tune/function_runner.py", line 267, in run
[2m[36m(pid=32077)[0m     raise e
[2m[36m(pid=32077)[0m   File "/zhome/45/c/127804/02460/python384/lib/python3.8/site-packages/ray/tune/function_runner.py", line 248, in run
[2m[36m(pid=32077)[0m     self._entrypoint()
[2m[36m(pid=32077)[0m   File "/zhome/45/c/127804/02460/python384/lib/python3.8/site-packages/ray/tune/function_runner.py", line 315, in entrypoint
[2m[36m(pid=32077)[0m     return self._trainable_func(self.config, self._status_reporter,
[2m[36m(pid=32077)[0m   File "/zhome/45/c/127804/02460/python384/lib/python3.8/site-packages/ray/tune/function_runner.py", line 580, in _trainable_func
[2m[36m(pid=32077)[0m     output = fn()
[2m[36m(pid=32077)[0m   File "grid_search_warm_up.py", line 94, in train_func
[2m[36m(pid=32077)[0m     loss, rl, kl      = vae.loss(x_hat, batch,p_mu,p_logvar,d_mu,d_logvar,alpha_warm_up =alpha_warm_up[k])
[2m[36m(pid=32077)[0m   File "/zhome/45/c/127804/02460/Variational_proteins/HVAE_v2.py", line 183, in loss
[2m[36m(pid=32077)[0m     p = Normal(p_mu[i], p_logvar[i].mul(1/2).exp())
[2m[36m(pid=32077)[0m   File "/zhome/45/c/127804/02460/python384/lib/python3.8/site-packages/torch/distributions/normal.py", line 50, in __init__
[2m[36m(pid=32077)[0m     super(Normal, self).__init__(batch_shape, validate_args=validate_args)
[2m[36m(pid=32077)[0m   File "/zhome/45/c/127804/02460/python384/lib/python3.8/site-packages/torch/distributions/distribution.py", line 53, in __init__
[2m[36m(pid=32077)[0m     raise ValueError("The parameter {} has invalid values".format(param))
[2m[36m(pid=32077)[0m ValueError: The parameter loc has invalid values
2021-05-01 21:43:27,372	ERROR trial_runner.py:732 -- Trial train_func_9c1c7_00029: Error processing event.
Traceback (most recent call last):
  File "/zhome/45/c/127804/02460/python384/lib/python3.8/site-packages/ray/tune/trial_runner.py", line 702, in _process_trial
    results = self.trial_executor.fetch_result(trial)
  File "/zhome/45/c/127804/02460/python384/lib/python3.8/site-packages/ray/tune/ray_trial_executor.py", line 686, in fetch_result
    result = ray.get(trial_future[0], timeout=DEFAULT_GET_TIMEOUT)
  File "/zhome/45/c/127804/02460/python384/lib/python3.8/site-packages/ray/_private/client_mode_hook.py", line 47, in wrapper
    return func(*args, **kwargs)
  File "/zhome/45/c/127804/02460/python384/lib/python3.8/site-packages/ray/worker.py", line 1481, in get
    raise value.as_instanceof_cause()
ray.exceptions.RayTaskError(TuneError): [36mray::ImplicitFunc.train_buffered()[39m (pid=32077, ip=10.66.20.3)
  File "python/ray/_raylet.pyx", line 505, in ray._raylet.execute_task
  File "python/ray/_raylet.pyx", line 449, in ray._raylet.execute_task.function_executor
  File "/zhome/45/c/127804/02460/python384/lib/python3.8/site-packages/ray/_private/function_manager.py", line 556, in actor_method_executor
    return method(__ray_actor, *args, **kwargs)
  File "/zhome/45/c/127804/02460/python384/lib/python3.8/site-packages/ray/tune/trainable.py", line 173, in train_buffered
    result = self.train()
  File "/zhome/45/c/127804/02460/python384/lib/python3.8/site-packages/ray/tune/trainable.py", line 232, in train
    result = self.step()
  File "/zhome/45/c/127804/02460/python384/lib/python3.8/site-packages/ray/tune/function_runner.py", line 366, in step
    self._report_thread_runner_error(block=True)
  File "/zhome/45/c/127804/02460/python384/lib/python3.8/site-packages/ray/tune/function_runner.py", line 512, in _report_thread_runner_error
    raise TuneError(
ray.tune.error.TuneError: Trial raised an exception. Traceback:
[36mray::ImplicitFunc.train_buffered()[39m (pid=32077, ip=10.66.20.3)
  File "/zhome/45/c/127804/02460/python384/lib/python3.8/site-packages/ray/tune/function_runner.py", line 248, in run
    self._entrypoint()
  File "/zhome/45/c/127804/02460/python384/lib/python3.8/site-packages/ray/tune/function_runner.py", line 315, in entrypoint
    return self._trainable_func(self.config, self._status_reporter,
  File "/zhome/45/c/127804/02460/python384/lib/python3.8/site-packages/ray/tune/function_runner.py", line 580, in _trainable_func
    output = fn()
  File "grid_search_warm_up.py", line 94, in train_func
    loss, rl, kl      = vae.loss(x_hat, batch,p_mu,p_logvar,d_mu,d_logvar,alpha_warm_up =alpha_warm_up[k])
  File "/zhome/45/c/127804/02460/Variational_proteins/HVAE_v2.py", line 183, in loss
    p = Normal(p_mu[i], p_logvar[i].mul(1/2).exp())
  File "/zhome/45/c/127804/02460/python384/lib/python3.8/site-packages/torch/distributions/normal.py", line 50, in __init__
    super(Normal, self).__init__(batch_shape, validate_args=validate_args)
  File "/zhome/45/c/127804/02460/python384/lib/python3.8/site-packages/torch/distributions/distribution.py", line 53, in __init__
    raise ValueError("The parameter {} has invalid values".format(param))
ValueError: The parameter loc has invalid values
2021-05-01 21:43:27,378	INFO logger.py:688 -- Removed the following hyperparameter values when logging to tensorboard: {'config/layers': (256, 256, 512), 'config/latents': (4, 4, 8)}
[2m[33m(raylet)[0m /zhome/45/c/127804/02460/python384/lib/python3.8/site-packages/ray/autoscaler/_private/cli_logger.py:57: FutureWarning: Not all Ray CLI dependencies were found. In Ray 1.4+, the Ray CLI, autoscaler, and dashboard will only be usable via `pip install 'ray[default]'`. Please update your install command.
[2m[33m(raylet)[0m   warnings.warn(
[2m[36m(pid=32594)[0m 2021-05-01 21:43:36,858	WARNING __init__.py:20 -- tune.track.log is now deprecated. Use `tune.report` instead. This warning will throw an error in a future version of Ray.
2021-05-01 21:57:04,754	INFO logger.py:688 -- Removed the following hyperparameter values when logging to tensorboard: {'config/layers': (256, 256, 512), 'config/latents': (4, 4, 16)}
[2m[33m(raylet)[0m /zhome/45/c/127804/02460/python384/lib/python3.8/site-packages/ray/autoscaler/_private/cli_logger.py:57: FutureWarning: Not all Ray CLI dependencies were found. In Ray 1.4+, the Ray CLI, autoscaler, and dashboard will only be usable via `pip install 'ray[default]'`. Please update your install command.
[2m[33m(raylet)[0m   warnings.warn(
[2m[36m(pid=971)[0m 2021-05-01 21:57:14,246	WARNING __init__.py:20 -- tune.track.log is now deprecated. Use `tune.report` instead. This warning will throw an error in a future version of Ray.
2021-05-01 22:10:48,431	INFO logger.py:688 -- Removed the following hyperparameter values when logging to tensorboard: {'config/layers': (256, 256, 512), 'config/latents': (4, 8, 8)}
[2m[33m(raylet)[0m /zhome/45/c/127804/02460/python384/lib/python3.8/site-packages/ray/autoscaler/_private/cli_logger.py:57: FutureWarning: Not all Ray CLI dependencies were found. In Ray 1.4+, the Ray CLI, autoscaler, and dashboard will only be usable via `pip install 'ray[default]'`. Please update your install command.
[2m[33m(raylet)[0m   warnings.warn(
[2m[36m(pid=1900)[0m 2021-05-01 22:10:57,975	WARNING __init__.py:20 -- tune.track.log is now deprecated. Use `tune.report` instead. This warning will throw an error in a future version of Ray.
[2m[36m(pid=1900)[0m 2021-05-01 22:11:22,274	ERROR function_runner.py:254 -- Runner Thread raised error.
[2m[36m(pid=1900)[0m Traceback (most recent call last):
[2m[36m(pid=1900)[0m   File "/zhome/45/c/127804/02460/python384/lib/python3.8/site-packages/ray/tune/function_runner.py", line 248, in run
[2m[36m(pid=1900)[0m     self._entrypoint()
[2m[36m(pid=1900)[0m   File "/zhome/45/c/127804/02460/python384/lib/python3.8/site-packages/ray/tune/function_runner.py", line 315, in entrypoint
[2m[36m(pid=1900)[0m     return self._trainable_func(self.config, self._status_reporter,
[2m[36m(pid=1900)[0m   File "/zhome/45/c/127804/02460/python384/lib/python3.8/site-packages/ray/tune/function_runner.py", line 580, in _trainable_func
[2m[36m(pid=1900)[0m     output = fn()
[2m[36m(pid=1900)[0m   File "grid_search_warm_up.py", line 94, in train_func
[2m[36m(pid=1900)[0m     loss, rl, kl      = vae.loss(x_hat, batch,p_mu,p_logvar,d_mu,d_logvar,alpha_warm_up =alpha_warm_up[k])
[2m[36m(pid=1900)[0m   File "/zhome/45/c/127804/02460/Variational_proteins/HVAE_v2.py", line 183, in loss
[2m[36m(pid=1900)[0m     p = Normal(p_mu[i], p_logvar[i].mul(1/2).exp())
[2m[36m(pid=1900)[0m   File "/zhome/45/c/127804/02460/python384/lib/python3.8/site-packages/torch/distributions/normal.py", line 50, in __init__
[2m[36m(pid=1900)[0m     super(Normal, self).__init__(batch_shape, validate_args=validate_args)
[2m[36m(pid=1900)[0m   File "/zhome/45/c/127804/02460/python384/lib/python3.8/site-packages/torch/distributions/distribution.py", line 53, in __init__
[2m[36m(pid=1900)[0m     raise ValueError("The parameter {} has invalid values".format(param))
[2m[36m(pid=1900)[0m ValueError: The parameter loc has invalid values
[2m[36m(pid=1900)[0m Exception in thread Thread-2:
[2m[36m(pid=1900)[0m Traceback (most recent call last):
[2m[36m(pid=1900)[0m   File "/appl/python/3.8.4/lib/python3.8/threading.py", line 932, in _bootstrap_inner
[2m[36m(pid=1900)[0m     self.run()
[2m[36m(pid=1900)[0m   File "/zhome/45/c/127804/02460/python384/lib/python3.8/site-packages/ray/tune/function_runner.py", line 267, in run
[2m[36m(pid=1900)[0m     raise e
[2m[36m(pid=1900)[0m   File "/zhome/45/c/127804/02460/python384/lib/python3.8/site-packages/ray/tune/function_runner.py", line 248, in run
[2m[36m(pid=1900)[0m     self._entrypoint()
[2m[36m(pid=1900)[0m   File "/zhome/45/c/127804/02460/python384/lib/python3.8/site-packages/ray/tune/function_runner.py", line 315, in entrypoint
[2m[36m(pid=1900)[0m     return self._trainable_func(self.config, self._status_reporter,
[2m[36m(pid=1900)[0m   File "/zhome/45/c/127804/02460/python384/lib/python3.8/site-packages/ray/tune/function_runner.py", line 580, in _trainable_func
[2m[36m(pid=1900)[0m     output = fn()
[2m[36m(pid=1900)[0m   File "grid_search_warm_up.py", line 94, in train_func
[2m[36m(pid=1900)[0m     loss, rl, kl      = vae.loss(x_hat, batch,p_mu,p_logvar,d_mu,d_logvar,alpha_warm_up =alpha_warm_up[k])
[2m[36m(pid=1900)[0m   File "/zhome/45/c/127804/02460/Variational_proteins/HVAE_v2.py", line 183, in loss
[2m[36m(pid=1900)[0m     p = Normal(p_mu[i], p_logvar[i].mul(1/2).exp())
[2m[36m(pid=1900)[0m   File "/zhome/45/c/127804/02460/python384/lib/python3.8/site-packages/torch/distributions/normal.py", line 50, in __init__
[2m[36m(pid=1900)[0m     super(Normal, self).__init__(batch_shape, validate_args=validate_args)
[2m[36m(pid=1900)[0m   File "/zhome/45/c/127804/02460/python384/lib/python3.8/site-packages/torch/distributions/distribution.py", line 53, in __init__
[2m[36m(pid=1900)[0m     raise ValueError("The parameter {} has invalid values".format(param))
[2m[36m(pid=1900)[0m ValueError: The parameter loc has invalid values
2021-05-01 22:11:22,379	ERROR trial_runner.py:732 -- Trial train_func_9c1c7_00032: Error processing event.
Traceback (most recent call last):
  File "/zhome/45/c/127804/02460/python384/lib/python3.8/site-packages/ray/tune/trial_runner.py", line 702, in _process_trial
    results = self.trial_executor.fetch_result(trial)
  File "/zhome/45/c/127804/02460/python384/lib/python3.8/site-packages/ray/tune/ray_trial_executor.py", line 686, in fetch_result
    result = ray.get(trial_future[0], timeout=DEFAULT_GET_TIMEOUT)
  File "/zhome/45/c/127804/02460/python384/lib/python3.8/site-packages/ray/_private/client_mode_hook.py", line 47, in wrapper
    return func(*args, **kwargs)
  File "/zhome/45/c/127804/02460/python384/lib/python3.8/site-packages/ray/worker.py", line 1481, in get
    raise value.as_instanceof_cause()
ray.exceptions.RayTaskError(TuneError): [36mray::ImplicitFunc.train_buffered()[39m (pid=1900, ip=10.66.20.3)
  File "python/ray/_raylet.pyx", line 505, in ray._raylet.execute_task
  File "python/ray/_raylet.pyx", line 449, in ray._raylet.execute_task.function_executor
  File "/zhome/45/c/127804/02460/python384/lib/python3.8/site-packages/ray/_private/function_manager.py", line 556, in actor_method_executor
    return method(__ray_actor, *args, **kwargs)
  File "/zhome/45/c/127804/02460/python384/lib/python3.8/site-packages/ray/tune/trainable.py", line 173, in train_buffered
    result = self.train()
  File "/zhome/45/c/127804/02460/python384/lib/python3.8/site-packages/ray/tune/trainable.py", line 232, in train
    result = self.step()
  File "/zhome/45/c/127804/02460/python384/lib/python3.8/site-packages/ray/tune/function_runner.py", line 366, in step
    self._report_thread_runner_error(block=True)
  File "/zhome/45/c/127804/02460/python384/lib/python3.8/site-packages/ray/tune/function_runner.py", line 512, in _report_thread_runner_error
    raise TuneError(
ray.tune.error.TuneError: Trial raised an exception. Traceback:
[36mray::ImplicitFunc.train_buffered()[39m (pid=1900, ip=10.66.20.3)
  File "/zhome/45/c/127804/02460/python384/lib/python3.8/site-packages/ray/tune/function_runner.py", line 248, in run
    self._entrypoint()
  File "/zhome/45/c/127804/02460/python384/lib/python3.8/site-packages/ray/tune/function_runner.py", line 315, in entrypoint
    return self._trainable_func(self.config, self._status_reporter,
  File "/zhome/45/c/127804/02460/python384/lib/python3.8/site-packages/ray/tune/function_runner.py", line 580, in _trainable_func
    output = fn()
  File "grid_search_warm_up.py", line 94, in train_func
    loss, rl, kl      = vae.loss(x_hat, batch,p_mu,p_logvar,d_mu,d_logvar,alpha_warm_up =alpha_warm_up[k])
  File "/zhome/45/c/127804/02460/Variational_proteins/HVAE_v2.py", line 183, in loss
    p = Normal(p_mu[i], p_logvar[i].mul(1/2).exp())
  File "/zhome/45/c/127804/02460/python384/lib/python3.8/site-packages/torch/distributions/normal.py", line 50, in __init__
    super(Normal, self).__init__(batch_shape, validate_args=validate_args)
  File "/zhome/45/c/127804/02460/python384/lib/python3.8/site-packages/torch/distributions/distribution.py", line 53, in __init__
    raise ValueError("The parameter {} has invalid values".format(param))
ValueError: The parameter loc has invalid values
2021-05-01 22:11:22,385	INFO logger.py:688 -- Removed the following hyperparameter values when logging to tensorboard: {'config/layers': (256, 256, 512), 'config/latents': (4, 8, 16)}
[2m[33m(raylet)[0m /zhome/45/c/127804/02460/python384/lib/python3.8/site-packages/ray/autoscaler/_private/cli_logger.py:57: FutureWarning: Not all Ray CLI dependencies were found. In Ray 1.4+, the Ray CLI, autoscaler, and dashboard will only be usable via `pip install 'ray[default]'`. Please update your install command.
[2m[33m(raylet)[0m   warnings.warn(
[2m[36m(pid=1959)[0m 2021-05-01 22:11:31,868	WARNING __init__.py:20 -- tune.track.log is now deprecated. Use `tune.report` instead. This warning will throw an error in a future version of Ray.
2021-05-01 22:25:03,999	INFO logger.py:688 -- Removed the following hyperparameter values when logging to tensorboard: {'config/layers': (256, 256, 512), 'config/latents': (4, 16, 16)}
[2m[33m(raylet)[0m /zhome/45/c/127804/02460/python384/lib/python3.8/site-packages/ray/autoscaler/_private/cli_logger.py:57: FutureWarning: Not all Ray CLI dependencies were found. In Ray 1.4+, the Ray CLI, autoscaler, and dashboard will only be usable via `pip install 'ray[default]'`. Please update your install command.
[2m[33m(raylet)[0m   warnings.warn(
[2m[36m(pid=2808)[0m 2021-05-01 22:25:13,508	WARNING __init__.py:20 -- tune.track.log is now deprecated. Use `tune.report` instead. This warning will throw an error in a future version of Ray.
2021-05-01 22:38:51,775	INFO logger.py:688 -- Removed the following hyperparameter values when logging to tensorboard: {'config/layers': (256, 256, 512), 'config/latents': (8, 8, 8)}
[2m[33m(raylet)[0m /zhome/45/c/127804/02460/python384/lib/python3.8/site-packages/ray/autoscaler/_private/cli_logger.py:57: FutureWarning: Not all Ray CLI dependencies were found. In Ray 1.4+, the Ray CLI, autoscaler, and dashboard will only be usable via `pip install 'ray[default]'`. Please update your install command.
[2m[33m(raylet)[0m   warnings.warn(
[2m[36m(pid=3631)[0m 2021-05-01 22:39:01,397	WARNING __init__.py:20 -- tune.track.log is now deprecated. Use `tune.report` instead. This warning will throw an error in a future version of Ray.
2021-05-01 22:52:30,280	INFO logger.py:688 -- Removed the following hyperparameter values when logging to tensorboard: {'config/layers': (256, 256, 512), 'config/latents': (8, 8, 16)}
[2m[33m(raylet)[0m /zhome/45/c/127804/02460/python384/lib/python3.8/site-packages/ray/autoscaler/_private/cli_logger.py:57: FutureWarning: Not all Ray CLI dependencies were found. In Ray 1.4+, the Ray CLI, autoscaler, and dashboard will only be usable via `pip install 'ray[default]'`. Please update your install command.
[2m[33m(raylet)[0m   warnings.warn(
[2m[36m(pid=4464)[0m 2021-05-01 22:52:39,887	WARNING __init__.py:20 -- tune.track.log is now deprecated. Use `tune.report` instead. This warning will throw an error in a future version of Ray.
2021-05-01 23:06:12,147	INFO logger.py:688 -- Removed the following hyperparameter values when logging to tensorboard: {'config/layers': (256, 256, 512), 'config/latents': (8, 16, 16)}
[2m[33m(raylet)[0m /zhome/45/c/127804/02460/python384/lib/python3.8/site-packages/ray/autoscaler/_private/cli_logger.py:57: FutureWarning: Not all Ray CLI dependencies were found. In Ray 1.4+, the Ray CLI, autoscaler, and dashboard will only be usable via `pip install 'ray[default]'`. Please update your install command.
[2m[33m(raylet)[0m   warnings.warn(
[2m[36m(pid=5303)[0m 2021-05-01 23:06:21,705	WARNING __init__.py:20 -- tune.track.log is now deprecated. Use `tune.report` instead. This warning will throw an error in a future version of Ray.
2021-05-01 23:19:49,671	INFO logger.py:688 -- Removed the following hyperparameter values when logging to tensorboard: {'config/layers': (256, 256, 512), 'config/latents': (16, 16, 16)}
[2m[33m(raylet)[0m /zhome/45/c/127804/02460/python384/lib/python3.8/site-packages/ray/autoscaler/_private/cli_logger.py:57: FutureWarning: Not all Ray CLI dependencies were found. In Ray 1.4+, the Ray CLI, autoscaler, and dashboard will only be usable via `pip install 'ray[default]'`. Please update your install command.
[2m[33m(raylet)[0m   warnings.warn(
[2m[36m(pid=6117)[0m 2021-05-01 23:19:59,213	WARNING __init__.py:20 -- tune.track.log is now deprecated. Use `tune.report` instead. This warning will throw an error in a future version of Ray.
2021-05-01 23:33:36,240	INFO logger.py:688 -- Removed the following hyperparameter values when logging to tensorboard: {'config/layers': (256, 512, 512), 'config/latents': (4, 4, 4)}
[2m[33m(raylet)[0m /zhome/45/c/127804/02460/python384/lib/python3.8/site-packages/ray/autoscaler/_private/cli_logger.py:57: FutureWarning: Not all Ray CLI dependencies were found. In Ray 1.4+, the Ray CLI, autoscaler, and dashboard will only be usable via `pip install 'ray[default]'`. Please update your install command.
[2m[33m(raylet)[0m   warnings.warn(
[2m[36m(pid=6956)[0m 2021-05-01 23:33:45,932	WARNING __init__.py:20 -- tune.track.log is now deprecated. Use `tune.report` instead. This warning will throw an error in a future version of Ray.
2021-05-01 23:47:31,894	INFO logger.py:688 -- Removed the following hyperparameter values when logging to tensorboard: {'config/layers': (256, 512, 512), 'config/latents': (4, 4, 8)}
[2m[33m(raylet)[0m /zhome/45/c/127804/02460/python384/lib/python3.8/site-packages/ray/autoscaler/_private/cli_logger.py:57: FutureWarning: Not all Ray CLI dependencies were found. In Ray 1.4+, the Ray CLI, autoscaler, and dashboard will only be usable via `pip install 'ray[default]'`. Please update your install command.
[2m[33m(raylet)[0m   warnings.warn(
[2m[36m(pid=7778)[0m 2021-05-01 23:47:41,467	WARNING __init__.py:20 -- tune.track.log is now deprecated. Use `tune.report` instead. This warning will throw an error in a future version of Ray.
2021-05-01 23:47:53,555	ERROR trial_runner.py:732 -- Trial train_func_9c1c7_00040: Error processing event.
Traceback (most recent call last):
  File "/zhome/45/c/127804/02460/python384/lib/python3.8/site-packages/ray/tune/trial_runner.py", line 702, in _process_trial
    results = self.trial_executor.fetch_result(trial)
  File "/zhome/45/c/127804/02460/python384/lib/python3.8/site-packages/ray/tune/ray_trial_executor.py", line 686, in fetch_result
    result = ray.get(trial_future[0], timeout=DEFAULT_GET_TIMEOUT)
  File "/zhome/45/c/127804/02460/python384/lib/python3.8/site-packages/ray/_private/client_mode_hook.py", line 47, in wrapper
    return func(*args, **kwargs)
  File "/zhome/45/c/127804/02460/python384/lib/python3.8/site-packages/ray/worker.py", line 1481, in get
    raise value.as_instanceof_cause()
ray.exceptions.RayTaskError(TuneError): [36mray::ImplicitFunc.train_buffered()[39m (pid=7778, ip=10.66.20.3)
  File "python/ray/_raylet.pyx", line 505, in ray._raylet.execute_task
  File "python/ray/_raylet.pyx", line 449, in ray._raylet.execute_task.function_executor
  File "/zhome/45/c/127804/02460/python384/lib/python3.8/site-packages/ray/_private/function_manager.py", line 556, in actor_method_executor
    return method(__ray_actor, *args, **kwargs)
  File "/zhome/45/c/127804/02460/python384/lib/python3.8/site-packages/ray/tune/trainable.py", line 173, in train_buffered
    result = self.train()
  File "/zhome/45/c/127804/02460/python384/lib/python3.8/site-packages/ray/tune/trainable.py", line 232, in train
    result = self.step()
  File "/zhome/45/c/127804/02460/python384/lib/python3.8/site-packages/ray/tune/function_runner.py", line 366, in step
    self._report_thread_runner_error(block=True)
  File "/zhome/45/c/127804/02460/python384/lib/python3.8/site-packages/ray/tune/function_runner.py", line 512, in _report_thread_runner_error
    raise TuneError(
ray.tune.error.TuneError: Trial raised an exception. Traceback:
[36mray::ImplicitFunc.train_buffered()[39m (pid=7778, ip=10.66.20.3)
  File "/zhome/45/c/127804/02460/python384/lib/python3.8/site-packages/ray/tune/function_runner.py", line 248, in run
    self._entrypoint()
  File "/zhome/45/c/127804/02460/python384/lib/python3.8/site-packages/ray/tune/function_runner.py", line 315, in entrypoint
    return self._trainable_func(self.config, self._status_reporter,
  File "/zhome/45/c/127804/02460/python384/lib/python3.8/site-packages/ray/tune/function_runner.py", line 580, in _trainable_func
    output = fn()
  File "grid_search_warm_up.py", line 94, in train_func
    loss, rl, kl      = vae.loss(x_hat, batch,p_mu,p_logvar,d_mu,d_logvar,alpha_warm_up =alpha_warm_up[k])
  File "/zhome/45/c/127804/02460/Variational_proteins/HVAE_v2.py", line 183, in loss
    p = Normal(p_mu[i], p_logvar[i].mul(1/2).exp())
  File "/zhome/45/c/127804/02460/python384/lib/python3.8/site-packages/torch/distributions/normal.py", line 50, in __init__
    super(Normal, self).__init__(batch_shape, validate_args=validate_args)
  File "/zhome/45/c/127804/02460/python384/lib/python3.8/site-packages/torch/distributions/distribution.py", line 53, in __init__
    raise ValueError("The parameter {} has invalid values".format(param))
ValueError: The parameter loc has invalid values
2021-05-01 23:47:53,563	INFO logger.py:688 -- Removed the following hyperparameter values when logging to tensorboard: {'config/layers': (256, 512, 512), 'config/latents': (4, 4, 16)}
[2m[36m(pid=7778)[0m 2021-05-01 23:47:53,509	ERROR function_runner.py:254 -- Runner Thread raised error.
[2m[36m(pid=7778)[0m Traceback (most recent call last):
[2m[36m(pid=7778)[0m   File "/zhome/45/c/127804/02460/python384/lib/python3.8/site-packages/ray/tune/function_runner.py", line 248, in run
[2m[36m(pid=7778)[0m     self._entrypoint()
[2m[36m(pid=7778)[0m   File "/zhome/45/c/127804/02460/python384/lib/python3.8/site-packages/ray/tune/function_runner.py", line 315, in entrypoint
[2m[36m(pid=7778)[0m     return self._trainable_func(self.config, self._status_reporter,
[2m[36m(pid=7778)[0m   File "/zhome/45/c/127804/02460/python384/lib/python3.8/site-packages/ray/tune/function_runner.py", line 580, in _trainable_func
[2m[36m(pid=7778)[0m     output = fn()
[2m[36m(pid=7778)[0m   File "grid_search_warm_up.py", line 94, in train_func
[2m[36m(pid=7778)[0m     loss, rl, kl      = vae.loss(x_hat, batch,p_mu,p_logvar,d_mu,d_logvar,alpha_warm_up =alpha_warm_up[k])
[2m[36m(pid=7778)[0m   File "/zhome/45/c/127804/02460/Variational_proteins/HVAE_v2.py", line 183, in loss
[2m[36m(pid=7778)[0m     p = Normal(p_mu[i], p_logvar[i].mul(1/2).exp())
[2m[36m(pid=7778)[0m   File "/zhome/45/c/127804/02460/python384/lib/python3.8/site-packages/torch/distributions/normal.py", line 50, in __init__
[2m[36m(pid=7778)[0m     super(Normal, self).__init__(batch_shape, validate_args=validate_args)
[2m[36m(pid=7778)[0m   File "/zhome/45/c/127804/02460/python384/lib/python3.8/site-packages/torch/distributions/distribution.py", line 53, in __init__
[2m[36m(pid=7778)[0m     raise ValueError("The parameter {} has invalid values".format(param))
[2m[36m(pid=7778)[0m ValueError: The parameter loc has invalid values
[2m[36m(pid=7778)[0m Exception in thread Thread-2:
[2m[36m(pid=7778)[0m Traceback (most recent call last):
[2m[36m(pid=7778)[0m   File "/appl/python/3.8.4/lib/python3.8/threading.py", line 932, in _bootstrap_inner
[2m[36m(pid=7778)[0m     self.run()
[2m[36m(pid=7778)[0m   File "/zhome/45/c/127804/02460/python384/lib/python3.8/site-packages/ray/tune/function_runner.py", line 267, in run
[2m[36m(pid=7778)[0m     raise e
[2m[36m(pid=7778)[0m   File "/zhome/45/c/127804/02460/python384/lib/python3.8/site-packages/ray/tune/function_runner.py", line 248, in run
[2m[36m(pid=7778)[0m     self._entrypoint()
[2m[36m(pid=7778)[0m   File "/zhome/45/c/127804/02460/python384/lib/python3.8/site-packages/ray/tune/function_runner.py", line 315, in entrypoint
[2m[36m(pid=7778)[0m     return self._trainable_func(self.config, self._status_reporter,
[2m[36m(pid=7778)[0m   File "/zhome/45/c/127804/02460/python384/lib/python3.8/site-packages/ray/tune/function_runner.py", line 580, in _trainable_func
[2m[36m(pid=7778)[0m     output = fn()
[2m[36m(pid=7778)[0m   File "grid_search_warm_up.py", line 94, in train_func
[2m[36m(pid=7778)[0m     loss, rl, kl      = vae.loss(x_hat, batch,p_mu,p_logvar,d_mu,d_logvar,alpha_warm_up =alpha_warm_up[k])
[2m[36m(pid=7778)[0m   File "/zhome/45/c/127804/02460/Variational_proteins/HVAE_v2.py", line 183, in loss
[2m[36m(pid=7778)[0m     p = Normal(p_mu[i], p_logvar[i].mul(1/2).exp())
[2m[36m(pid=7778)[0m   File "/zhome/45/c/127804/02460/python384/lib/python3.8/site-packages/torch/distributions/normal.py", line 50, in __init__
[2m[36m(pid=7778)[0m     super(Normal, self).__init__(batch_shape, validate_args=validate_args)
[2m[36m(pid=7778)[0m   File "/zhome/45/c/127804/02460/python384/lib/python3.8/site-packages/torch/distributions/distribution.py", line 53, in __init__
[2m[36m(pid=7778)[0m     raise ValueError("The parameter {} has invalid values".format(param))
[2m[36m(pid=7778)[0m ValueError: The parameter loc has invalid values
[2m[33m(raylet)[0m /zhome/45/c/127804/02460/python384/lib/python3.8/site-packages/ray/autoscaler/_private/cli_logger.py:57: FutureWarning: Not all Ray CLI dependencies were found. In Ray 1.4+, the Ray CLI, autoscaler, and dashboard will only be usable via `pip install 'ray[default]'`. Please update your install command.
[2m[33m(raylet)[0m   warnings.warn(
[2m[36m(pid=7831)[0m 2021-05-01 23:48:03,151	WARNING __init__.py:20 -- tune.track.log is now deprecated. Use `tune.report` instead. This warning will throw an error in a future version of Ray.
[2m[36m(pid=7831)[0m 2021-05-01 23:48:19,597	ERROR function_runner.py:254 -- Runner Thread raised error.
[2m[36m(pid=7831)[0m Traceback (most recent call last):
[2m[36m(pid=7831)[0m   File "/zhome/45/c/127804/02460/python384/lib/python3.8/site-packages/ray/tune/function_runner.py", line 248, in run
[2m[36m(pid=7831)[0m     self._entrypoint()
[2m[36m(pid=7831)[0m   File "/zhome/45/c/127804/02460/python384/lib/python3.8/site-packages/ray/tune/function_runner.py", line 315, in entrypoint
[2m[36m(pid=7831)[0m     return self._trainable_func(self.config, self._status_reporter,
[2m[36m(pid=7831)[0m   File "/zhome/45/c/127804/02460/python384/lib/python3.8/site-packages/ray/tune/function_runner.py", line 580, in _trainable_func
[2m[36m(pid=7831)[0m     output = fn()
[2m[36m(pid=7831)[0m   File "grid_search_warm_up.py", line 94, in train_func
[2m[36m(pid=7831)[0m     loss, rl, kl      = vae.loss(x_hat, batch,p_mu,p_logvar,d_mu,d_logvar,alpha_warm_up =alpha_warm_up[k])
[2m[36m(pid=7831)[0m   File "/zhome/45/c/127804/02460/Variational_proteins/HVAE_v2.py", line 183, in loss
[2m[36m(pid=7831)[0m     p = Normal(p_mu[i], p_logvar[i].mul(1/2).exp())
[2m[36m(pid=7831)[0m   File "/zhome/45/c/127804/02460/python384/lib/python3.8/site-packages/torch/distributions/normal.py", line 50, in __init__
[2m[36m(pid=7831)[0m     super(Normal, self).__init__(batch_shape, validate_args=validate_args)
[2m[36m(pid=7831)[0m   File "/zhome/45/c/127804/02460/python384/lib/python3.8/site-packages/torch/distributions/distribution.py", line 53, in __init__
[2m[36m(pid=7831)[0m     raise ValueError("The parameter {} has invalid values".format(param))
[2m[36m(pid=7831)[0m ValueError: The parameter loc has invalid values
[2m[36m(pid=7831)[0m Exception in thread Thread-2:
[2m[36m(pid=7831)[0m Traceback (most recent call last):
[2m[36m(pid=7831)[0m   File "/appl/python/3.8.4/lib/python3.8/threading.py", line 932, in _bootstrap_inner
[2m[36m(pid=7831)[0m     self.run()
[2m[36m(pid=7831)[0m   File "/zhome/45/c/127804/02460/python384/lib/python3.8/site-packages/ray/tune/function_runner.py", line 267, in run
[2m[36m(pid=7831)[0m     raise e
[2m[36m(pid=7831)[0m   File "/zhome/45/c/127804/02460/python384/lib/python3.8/site-packages/ray/tune/function_runner.py", line 248, in run
[2m[36m(pid=7831)[0m     self._entrypoint()
[2m[36m(pid=7831)[0m   File "/zhome/45/c/127804/02460/python384/lib/python3.8/site-packages/ray/tune/function_runner.py", line 315, in entrypoint
[2m[36m(pid=7831)[0m     return self._trainable_func(self.config, self._status_reporter,
[2m[36m(pid=7831)[0m   File "/zhome/45/c/127804/02460/python384/lib/python3.8/site-packages/ray/tune/function_runner.py", line 580, in _trainable_func
[2m[36m(pid=7831)[0m     output = fn()
[2m[36m(pid=7831)[0m   File "grid_search_warm_up.py", line 94, in train_func
[2m[36m(pid=7831)[0m     loss, rl, kl      = vae.loss(x_hat, batch,p_mu,p_logvar,d_mu,d_logvar,alpha_warm_up =alpha_warm_up[k])
[2m[36m(pid=7831)[0m   File "/zhome/45/c/127804/02460/Variational_proteins/HVAE_v2.py", line 183, in loss
[2m[36m(pid=7831)[0m     p = Normal(p_mu[i], p_logvar[i].mul(1/2).exp())
[2m[36m(pid=7831)[0m   File "/zhome/45/c/127804/02460/python384/lib/python3.8/site-packages/torch/distributions/normal.py", line 50, in __init__
[2m[36m(pid=7831)[0m     super(Normal, self).__init__(batch_shape, validate_args=validate_args)
[2m[36m(pid=7831)[0m   File "/zhome/45/c/127804/02460/python384/lib/python3.8/site-packages/torch/distributions/distribution.py", line 53, in __init__
[2m[36m(pid=7831)[0m     raise ValueError("The parameter {} has invalid values".format(param))
[2m[36m(pid=7831)[0m ValueError: The parameter loc has invalid values
2021-05-01 23:48:19,746	ERROR trial_runner.py:732 -- Trial train_func_9c1c7_00041: Error processing event.
Traceback (most recent call last):
  File "/zhome/45/c/127804/02460/python384/lib/python3.8/site-packages/ray/tune/trial_runner.py", line 702, in _process_trial
    results = self.trial_executor.fetch_result(trial)
  File "/zhome/45/c/127804/02460/python384/lib/python3.8/site-packages/ray/tune/ray_trial_executor.py", line 686, in fetch_result
    result = ray.get(trial_future[0], timeout=DEFAULT_GET_TIMEOUT)
  File "/zhome/45/c/127804/02460/python384/lib/python3.8/site-packages/ray/_private/client_mode_hook.py", line 47, in wrapper
    return func(*args, **kwargs)
  File "/zhome/45/c/127804/02460/python384/lib/python3.8/site-packages/ray/worker.py", line 1481, in get
    raise value.as_instanceof_cause()
ray.exceptions.RayTaskError(TuneError): [36mray::ImplicitFunc.train_buffered()[39m (pid=7831, ip=10.66.20.3)
  File "python/ray/_raylet.pyx", line 505, in ray._raylet.execute_task
  File "python/ray/_raylet.pyx", line 449, in ray._raylet.execute_task.function_executor
  File "/zhome/45/c/127804/02460/python384/lib/python3.8/site-packages/ray/_private/function_manager.py", line 556, in actor_method_executor
    return method(__ray_actor, *args, **kwargs)
  File "/zhome/45/c/127804/02460/python384/lib/python3.8/site-packages/ray/tune/trainable.py", line 173, in train_buffered
    result = self.train()
  File "/zhome/45/c/127804/02460/python384/lib/python3.8/site-packages/ray/tune/trainable.py", line 232, in train
    result = self.step()
  File "/zhome/45/c/127804/02460/python384/lib/python3.8/site-packages/ray/tune/function_runner.py", line 366, in step
    self._report_thread_runner_error(block=True)
  File "/zhome/45/c/127804/02460/python384/lib/python3.8/site-packages/ray/tune/function_runner.py", line 512, in _report_thread_runner_error
    raise TuneError(
ray.tune.error.TuneError: Trial raised an exception. Traceback:
[36mray::ImplicitFunc.train_buffered()[39m (pid=7831, ip=10.66.20.3)
  File "/zhome/45/c/127804/02460/python384/lib/python3.8/site-packages/ray/tune/function_runner.py", line 248, in run
    self._entrypoint()
  File "/zhome/45/c/127804/02460/python384/lib/python3.8/site-packages/ray/tune/function_runner.py", line 315, in entrypoint
    return self._trainable_func(self.config, self._status_reporter,
  File "/zhome/45/c/127804/02460/python384/lib/python3.8/site-packages/ray/tune/function_runner.py", line 580, in _trainable_func
    output = fn()
  File "grid_search_warm_up.py", line 94, in train_func
    loss, rl, kl      = vae.loss(x_hat, batch,p_mu,p_logvar,d_mu,d_logvar,alpha_warm_up =alpha_warm_up[k])
  File "/zhome/45/c/127804/02460/Variational_proteins/HVAE_v2.py", line 183, in loss
    p = Normal(p_mu[i], p_logvar[i].mul(1/2).exp())
  File "/zhome/45/c/127804/02460/python384/lib/python3.8/site-packages/torch/distributions/normal.py", line 50, in __init__
    super(Normal, self).__init__(batch_shape, validate_args=validate_args)
  File "/zhome/45/c/127804/02460/python384/lib/python3.8/site-packages/torch/distributions/distribution.py", line 53, in __init__
    raise ValueError("The parameter {} has invalid values".format(param))
ValueError: The parameter loc has invalid values
2021-05-01 23:48:19,751	INFO logger.py:688 -- Removed the following hyperparameter values when logging to tensorboard: {'config/layers': (256, 512, 512), 'config/latents': (4, 8, 8)}
[2m[33m(raylet)[0m /zhome/45/c/127804/02460/python384/lib/python3.8/site-packages/ray/autoscaler/_private/cli_logger.py:57: FutureWarning: Not all Ray CLI dependencies were found. In Ray 1.4+, the Ray CLI, autoscaler, and dashboard will only be usable via `pip install 'ray[default]'`. Please update your install command.
[2m[33m(raylet)[0m   warnings.warn(
[2m[36m(pid=7881)[0m 2021-05-01 23:48:29,337	WARNING __init__.py:20 -- tune.track.log is now deprecated. Use `tune.report` instead. This warning will throw an error in a future version of Ray.
2021-05-02 00:02:12,316	INFO logger.py:688 -- Removed the following hyperparameter values when logging to tensorboard: {'config/layers': (256, 512, 512), 'config/latents': (4, 8, 16)}
[2m[33m(raylet)[0m /zhome/45/c/127804/02460/python384/lib/python3.8/site-packages/ray/autoscaler/_private/cli_logger.py:57: FutureWarning: Not all Ray CLI dependencies were found. In Ray 1.4+, the Ray CLI, autoscaler, and dashboard will only be usable via `pip install 'ray[default]'`. Please update your install command.
[2m[33m(raylet)[0m   warnings.warn(
[2m[36m(pid=8758)[0m 2021-05-02 00:02:21,875	WARNING __init__.py:20 -- tune.track.log is now deprecated. Use `tune.report` instead. This warning will throw an error in a future version of Ray.
2021-05-02 00:16:12,057	INFO logger.py:688 -- Removed the following hyperparameter values when logging to tensorboard: {'config/layers': (256, 512, 512), 'config/latents': (4, 16, 16)}
[2m[33m(raylet)[0m /zhome/45/c/127804/02460/python384/lib/python3.8/site-packages/ray/autoscaler/_private/cli_logger.py:57: FutureWarning: Not all Ray CLI dependencies were found. In Ray 1.4+, the Ray CLI, autoscaler, and dashboard will only be usable via `pip install 'ray[default]'`. Please update your install command.
[2m[33m(raylet)[0m   warnings.warn(
[2m[36m(pid=9709)[0m 2021-05-02 00:16:21,864	WARNING __init__.py:20 -- tune.track.log is now deprecated. Use `tune.report` instead. This warning will throw an error in a future version of Ray.
[2m[36m(pid=9709)[0m 2021-05-02 00:16:34,173	ERROR function_runner.py:254 -- Runner Thread raised error.
[2m[36m(pid=9709)[0m Traceback (most recent call last):
[2m[36m(pid=9709)[0m   File "/zhome/45/c/127804/02460/python384/lib/python3.8/site-packages/ray/tune/function_runner.py", line 248, in run
[2m[36m(pid=9709)[0m     self._entrypoint()
[2m[36m(pid=9709)[0m   File "/zhome/45/c/127804/02460/python384/lib/python3.8/site-packages/ray/tune/function_runner.py", line 315, in entrypoint
[2m[36m(pid=9709)[0m     return self._trainable_func(self.config, self._status_reporter,
[2m[36m(pid=9709)[0m   File "/zhome/45/c/127804/02460/python384/lib/python3.8/site-packages/ray/tune/function_runner.py", line 580, in _trainable_func
[2m[36m(pid=9709)[0m     output = fn()
[2m[36m(pid=9709)[0m   File "grid_search_warm_up.py", line 94, in train_func
[2m[36m(pid=9709)[0m     loss, rl, kl      = vae.loss(x_hat, batch,p_mu,p_logvar,d_mu,d_logvar,alpha_warm_up =alpha_warm_up[k])
[2m[36m(pid=9709)[0m   File "/zhome/45/c/127804/02460/Variational_proteins/HVAE_v2.py", line 183, in loss
[2m[36m(pid=9709)[0m     p = Normal(p_mu[i], p_logvar[i].mul(1/2).exp())
[2m[36m(pid=9709)[0m   File "/zhome/45/c/127804/02460/python384/lib/python3.8/site-packages/torch/distributions/normal.py", line 50, in __init__
[2m[36m(pid=9709)[0m     super(Normal, self).__init__(batch_shape, validate_args=validate_args)
[2m[36m(pid=9709)[0m   File "/zhome/45/c/127804/02460/python384/lib/python3.8/site-packages/torch/distributions/distribution.py", line 53, in __init__
[2m[36m(pid=9709)[0m     raise ValueError("The parameter {} has invalid values".format(param))
[2m[36m(pid=9709)[0m ValueError: The parameter loc has invalid values
[2m[36m(pid=9709)[0m Exception in thread Thread-2:
[2m[36m(pid=9709)[0m Traceback (most recent call last):
[2m[36m(pid=9709)[0m   File "/appl/python/3.8.4/lib/python3.8/threading.py", line 932, in _bootstrap_inner
[2m[36m(pid=9709)[0m     self.run()
[2m[36m(pid=9709)[0m   File "/zhome/45/c/127804/02460/python384/lib/python3.8/site-packages/ray/tune/function_runner.py", line 267, in run
[2m[36m(pid=9709)[0m     raise e
[2m[36m(pid=9709)[0m   File "/zhome/45/c/127804/02460/python384/lib/python3.8/site-packages/ray/tune/function_runner.py", line 248, in run
[2m[36m(pid=9709)[0m     self._entrypoint()
[2m[36m(pid=9709)[0m   File "/zhome/45/c/127804/02460/python384/lib/python3.8/site-packages/ray/tune/function_runner.py", line 315, in entrypoint
[2m[36m(pid=9709)[0m     return self._trainable_func(self.config, self._status_reporter,
[2m[36m(pid=9709)[0m   File "/zhome/45/c/127804/02460/python384/lib/python3.8/site-packages/ray/tune/function_runner.py", line 580, in _trainable_func
[2m[36m(pid=9709)[0m     output = fn()
[2m[36m(pid=9709)[0m   File "grid_search_warm_up.py", line 94, in train_func
[2m[36m(pid=9709)[0m     loss, rl, kl      = vae.loss(x_hat, batch,p_mu,p_logvar,d_mu,d_logvar,alpha_warm_up =alpha_warm_up[k])
[2m[36m(pid=9709)[0m   File "/zhome/45/c/127804/02460/Variational_proteins/HVAE_v2.py", line 183, in loss
[2m[36m(pid=9709)[0m     p = Normal(p_mu[i], p_logvar[i].mul(1/2).exp())
[2m[36m(pid=9709)[0m   File "/zhome/45/c/127804/02460/python384/lib/python3.8/site-packages/torch/distributions/normal.py", line 50, in __init__
[2m[36m(pid=9709)[0m     super(Normal, self).__init__(batch_shape, validate_args=validate_args)
[2m[36m(pid=9709)[0m   File "/zhome/45/c/127804/02460/python384/lib/python3.8/site-packages/torch/distributions/distribution.py", line 53, in __init__
[2m[36m(pid=9709)[0m     raise ValueError("The parameter {} has invalid values".format(param))
[2m[36m(pid=9709)[0m ValueError: The parameter loc has invalid values
2021-05-02 00:16:34,309	ERROR trial_runner.py:732 -- Trial train_func_9c1c7_00044: Error processing event.
Traceback (most recent call last):
  File "/zhome/45/c/127804/02460/python384/lib/python3.8/site-packages/ray/tune/trial_runner.py", line 702, in _process_trial
    results = self.trial_executor.fetch_result(trial)
  File "/zhome/45/c/127804/02460/python384/lib/python3.8/site-packages/ray/tune/ray_trial_executor.py", line 686, in fetch_result
    result = ray.get(trial_future[0], timeout=DEFAULT_GET_TIMEOUT)
  File "/zhome/45/c/127804/02460/python384/lib/python3.8/site-packages/ray/_private/client_mode_hook.py", line 47, in wrapper
    return func(*args, **kwargs)
  File "/zhome/45/c/127804/02460/python384/lib/python3.8/site-packages/ray/worker.py", line 1481, in get
    raise value.as_instanceof_cause()
ray.exceptions.RayTaskError(TuneError): [36mray::ImplicitFunc.train_buffered()[39m (pid=9709, ip=10.66.20.3)
  File "python/ray/_raylet.pyx", line 505, in ray._raylet.execute_task
  File "python/ray/_raylet.pyx", line 449, in ray._raylet.execute_task.function_executor
  File "/zhome/45/c/127804/02460/python384/lib/python3.8/site-packages/ray/_private/function_manager.py", line 556, in actor_method_executor
    return method(__ray_actor, *args, **kwargs)
  File "/zhome/45/c/127804/02460/python384/lib/python3.8/site-packages/ray/tune/trainable.py", line 173, in train_buffered
    result = self.train()
  File "/zhome/45/c/127804/02460/python384/lib/python3.8/site-packages/ray/tune/trainable.py", line 232, in train
    result = self.step()
  File "/zhome/45/c/127804/02460/python384/lib/python3.8/site-packages/ray/tune/function_runner.py", line 366, in step
    self._report_thread_runner_error(block=True)
  File "/zhome/45/c/127804/02460/python384/lib/python3.8/site-packages/ray/tune/function_runner.py", line 512, in _report_thread_runner_error
    raise TuneError(
ray.tune.error.TuneError: Trial raised an exception. Traceback:
[36mray::ImplicitFunc.train_buffered()[39m (pid=9709, ip=10.66.20.3)
  File "/zhome/45/c/127804/02460/python384/lib/python3.8/site-packages/ray/tune/function_runner.py", line 248, in run
    self._entrypoint()
  File "/zhome/45/c/127804/02460/python384/lib/python3.8/site-packages/ray/tune/function_runner.py", line 315, in entrypoint
    return self._trainable_func(self.config, self._status_reporter,
  File "/zhome/45/c/127804/02460/python384/lib/python3.8/site-packages/ray/tune/function_runner.py", line 580, in _trainable_func
    output = fn()
  File "grid_search_warm_up.py", line 94, in train_func
    loss, rl, kl      = vae.loss(x_hat, batch,p_mu,p_logvar,d_mu,d_logvar,alpha_warm_up =alpha_warm_up[k])
  File "/zhome/45/c/127804/02460/Variational_proteins/HVAE_v2.py", line 183, in loss
    p = Normal(p_mu[i], p_logvar[i].mul(1/2).exp())
  File "/zhome/45/c/127804/02460/python384/lib/python3.8/site-packages/torch/distributions/normal.py", line 50, in __init__
    super(Normal, self).__init__(batch_shape, validate_args=validate_args)
  File "/zhome/45/c/127804/02460/python384/lib/python3.8/site-packages/torch/distributions/distribution.py", line 53, in __init__
    raise ValueError("The parameter {} has invalid values".format(param))
ValueError: The parameter loc has invalid values
2021-05-02 00:16:34,318	INFO logger.py:688 -- Removed the following hyperparameter values when logging to tensorboard: {'config/layers': (256, 512, 512), 'config/latents': (8, 8, 8)}
[2m[33m(raylet)[0m /zhome/45/c/127804/02460/python384/lib/python3.8/site-packages/ray/autoscaler/_private/cli_logger.py:57: FutureWarning: Not all Ray CLI dependencies were found. In Ray 1.4+, the Ray CLI, autoscaler, and dashboard will only be usable via `pip install 'ray[default]'`. Please update your install command.
[2m[33m(raylet)[0m   warnings.warn(
[2m[36m(pid=9758)[0m 2021-05-02 00:16:44,011	WARNING __init__.py:20 -- tune.track.log is now deprecated. Use `tune.report` instead. This warning will throw an error in a future version of Ray.
[2m[36m(pid=9758)[0m 2021-05-02 00:17:00,255	ERROR function_runner.py:254 -- Runner Thread raised error.
[2m[36m(pid=9758)[0m Traceback (most recent call last):
[2m[36m(pid=9758)[0m   File "/zhome/45/c/127804/02460/python384/lib/python3.8/site-packages/ray/tune/function_runner.py", line 248, in run
[2m[36m(pid=9758)[0m     self._entrypoint()
[2m[36m(pid=9758)[0m   File "/zhome/45/c/127804/02460/python384/lib/python3.8/site-packages/ray/tune/function_runner.py", line 315, in entrypoint
[2m[36m(pid=9758)[0m     return self._trainable_func(self.config, self._status_reporter,
[2m[36m(pid=9758)[0m   File "/zhome/45/c/127804/02460/python384/lib/python3.8/site-packages/ray/tune/function_runner.py", line 580, in _trainable_func
[2m[36m(pid=9758)[0m     output = fn()
[2m[36m(pid=9758)[0m   File "grid_search_warm_up.py", line 94, in train_func
[2m[36m(pid=9758)[0m     loss, rl, kl      = vae.loss(x_hat, batch,p_mu,p_logvar,d_mu,d_logvar,alpha_warm_up =alpha_warm_up[k])
[2m[36m(pid=9758)[0m   File "/zhome/45/c/127804/02460/Variational_proteins/HVAE_v2.py", line 183, in loss
[2m[36m(pid=9758)[0m     p = Normal(p_mu[i], p_logvar[i].mul(1/2).exp())
[2m[36m(pid=9758)[0m   File "/zhome/45/c/127804/02460/python384/lib/python3.8/site-packages/torch/distributions/normal.py", line 50, in __init__
[2m[36m(pid=9758)[0m     super(Normal, self).__init__(batch_shape, validate_args=validate_args)
[2m[36m(pid=9758)[0m   File "/zhome/45/c/127804/02460/python384/lib/python3.8/site-packages/torch/distributions/distribution.py", line 53, in __init__
[2m[36m(pid=9758)[0m     raise ValueError("The parameter {} has invalid values".format(param))
[2m[36m(pid=9758)[0m ValueError: The parameter loc has invalid values
[2m[36m(pid=9758)[0m Exception in thread Thread-2:
[2m[36m(pid=9758)[0m Traceback (most recent call last):
[2m[36m(pid=9758)[0m   File "/appl/python/3.8.4/lib/python3.8/threading.py", line 932, in _bootstrap_inner
[2m[36m(pid=9758)[0m     self.run()
[2m[36m(pid=9758)[0m   File "/zhome/45/c/127804/02460/python384/lib/python3.8/site-packages/ray/tune/function_runner.py", line 267, in run
[2m[36m(pid=9758)[0m     raise e
[2m[36m(pid=9758)[0m   File "/zhome/45/c/127804/02460/python384/lib/python3.8/site-packages/ray/tune/function_runner.py", line 248, in run
[2m[36m(pid=9758)[0m     self._entrypoint()
[2m[36m(pid=9758)[0m   File "/zhome/45/c/127804/02460/python384/lib/python3.8/site-packages/ray/tune/function_runner.py", line 315, in entrypoint
[2m[36m(pid=9758)[0m     return self._trainable_func(self.config, self._status_reporter,
[2m[36m(pid=9758)[0m   File "/zhome/45/c/127804/02460/python384/lib/python3.8/site-packages/ray/tune/function_runner.py", line 580, in _trainable_func
[2m[36m(pid=9758)[0m     output = fn()
[2m[36m(pid=9758)[0m   File "grid_search_warm_up.py", line 94, in train_func
[2m[36m(pid=9758)[0m     loss, rl, kl      = vae.loss(x_hat, batch,p_mu,p_logvar,d_mu,d_logvar,alpha_warm_up =alpha_warm_up[k])
[2m[36m(pid=9758)[0m   File "/zhome/45/c/127804/02460/Variational_proteins/HVAE_v2.py", line 183, in loss
[2m[36m(pid=9758)[0m     p = Normal(p_mu[i], p_logvar[i].mul(1/2).exp())
[2m[36m(pid=9758)[0m   File "/zhome/45/c/127804/02460/python384/lib/python3.8/site-packages/torch/distributions/normal.py", line 50, in __init__
[2m[36m(pid=9758)[0m     super(Normal, self).__init__(batch_shape, validate_args=validate_args)
[2m[36m(pid=9758)[0m   File "/zhome/45/c/127804/02460/python384/lib/python3.8/site-packages/torch/distributions/distribution.py", line 53, in __init__
[2m[36m(pid=9758)[0m     raise ValueError("The parameter {} has invalid values".format(param))
[2m[36m(pid=9758)[0m ValueError: The parameter loc has invalid values
2021-05-02 00:17:00,456	ERROR trial_runner.py:732 -- Trial train_func_9c1c7_00045: Error processing event.
Traceback (most recent call last):
  File "/zhome/45/c/127804/02460/python384/lib/python3.8/site-packages/ray/tune/trial_runner.py", line 702, in _process_trial
    results = self.trial_executor.fetch_result(trial)
  File "/zhome/45/c/127804/02460/python384/lib/python3.8/site-packages/ray/tune/ray_trial_executor.py", line 686, in fetch_result
    result = ray.get(trial_future[0], timeout=DEFAULT_GET_TIMEOUT)
  File "/zhome/45/c/127804/02460/python384/lib/python3.8/site-packages/ray/_private/client_mode_hook.py", line 47, in wrapper
    return func(*args, **kwargs)
  File "/zhome/45/c/127804/02460/python384/lib/python3.8/site-packages/ray/worker.py", line 1481, in get
    raise value.as_instanceof_cause()
ray.exceptions.RayTaskError(TuneError): [36mray::ImplicitFunc.train_buffered()[39m (pid=9758, ip=10.66.20.3)
  File "python/ray/_raylet.pyx", line 505, in ray._raylet.execute_task
  File "python/ray/_raylet.pyx", line 449, in ray._raylet.execute_task.function_executor
  File "/zhome/45/c/127804/02460/python384/lib/python3.8/site-packages/ray/_private/function_manager.py", line 556, in actor_method_executor
    return method(__ray_actor, *args, **kwargs)
  File "/zhome/45/c/127804/02460/python384/lib/python3.8/site-packages/ray/tune/trainable.py", line 173, in train_buffered
    result = self.train()
  File "/zhome/45/c/127804/02460/python384/lib/python3.8/site-packages/ray/tune/trainable.py", line 232, in train
    result = self.step()
  File "/zhome/45/c/127804/02460/python384/lib/python3.8/site-packages/ray/tune/function_runner.py", line 366, in step
    self._report_thread_runner_error(block=True)
  File "/zhome/45/c/127804/02460/python384/lib/python3.8/site-packages/ray/tune/function_runner.py", line 512, in _report_thread_runner_error
    raise TuneError(
ray.tune.error.TuneError: Trial raised an exception. Traceback:
[36mray::ImplicitFunc.train_buffered()[39m (pid=9758, ip=10.66.20.3)
  File "/zhome/45/c/127804/02460/python384/lib/python3.8/site-packages/ray/tune/function_runner.py", line 248, in run
    self._entrypoint()
  File "/zhome/45/c/127804/02460/python384/lib/python3.8/site-packages/ray/tune/function_runner.py", line 315, in entrypoint
    return self._trainable_func(self.config, self._status_reporter,
  File "/zhome/45/c/127804/02460/python384/lib/python3.8/site-packages/ray/tune/function_runner.py", line 580, in _trainable_func
    output = fn()
  File "grid_search_warm_up.py", line 94, in train_func
    loss, rl, kl      = vae.loss(x_hat, batch,p_mu,p_logvar,d_mu,d_logvar,alpha_warm_up =alpha_warm_up[k])
  File "/zhome/45/c/127804/02460/Variational_proteins/HVAE_v2.py", line 183, in loss
    p = Normal(p_mu[i], p_logvar[i].mul(1/2).exp())
  File "/zhome/45/c/127804/02460/python384/lib/python3.8/site-packages/torch/distributions/normal.py", line 50, in __init__
    super(Normal, self).__init__(batch_shape, validate_args=validate_args)
  File "/zhome/45/c/127804/02460/python384/lib/python3.8/site-packages/torch/distributions/distribution.py", line 53, in __init__
    raise ValueError("The parameter {} has invalid values".format(param))
ValueError: The parameter loc has invalid values
2021-05-02 00:17:00,461	INFO logger.py:688 -- Removed the following hyperparameter values when logging to tensorboard: {'config/layers': (256, 512, 512), 'config/latents': (8, 8, 16)}
[2m[33m(raylet)[0m /zhome/45/c/127804/02460/python384/lib/python3.8/site-packages/ray/autoscaler/_private/cli_logger.py:57: FutureWarning: Not all Ray CLI dependencies were found. In Ray 1.4+, the Ray CLI, autoscaler, and dashboard will only be usable via `pip install 'ray[default]'`. Please update your install command.
[2m[33m(raylet)[0m   warnings.warn(
[2m[36m(pid=9808)[0m 2021-05-02 00:17:10,181	WARNING __init__.py:20 -- tune.track.log is now deprecated. Use `tune.report` instead. This warning will throw an error in a future version of Ray.
2021-05-02 00:31:01,838	INFO logger.py:688 -- Removed the following hyperparameter values when logging to tensorboard: {'config/layers': (256, 512, 512), 'config/latents': (8, 16, 16)}
[2m[33m(raylet)[0m /zhome/45/c/127804/02460/python384/lib/python3.8/site-packages/ray/autoscaler/_private/cli_logger.py:57: FutureWarning: Not all Ray CLI dependencies were found. In Ray 1.4+, the Ray CLI, autoscaler, and dashboard will only be usable via `pip install 'ray[default]'`. Please update your install command.
[2m[33m(raylet)[0m   warnings.warn(
[2m[36m(pid=10651)[0m 2021-05-02 00:31:13,577	WARNING __init__.py:20 -- tune.track.log is now deprecated. Use `tune.report` instead. This warning will throw an error in a future version of Ray.
2021-05-02 00:45:04,097	INFO logger.py:688 -- Removed the following hyperparameter values when logging to tensorboard: {'config/layers': (256, 512, 512), 'config/latents': (16, 16, 16)}
[2m[33m(raylet)[0m /zhome/45/c/127804/02460/python384/lib/python3.8/site-packages/ray/autoscaler/_private/cli_logger.py:57: FutureWarning: Not all Ray CLI dependencies were found. In Ray 1.4+, the Ray CLI, autoscaler, and dashboard will only be usable via `pip install 'ray[default]'`. Please update your install command.
[2m[33m(raylet)[0m   warnings.warn(
[2m[36m(pid=11491)[0m 2021-05-02 00:45:14,619	WARNING __init__.py:20 -- tune.track.log is now deprecated. Use `tune.report` instead. This warning will throw an error in a future version of Ray.
[2m[36m(pid=11491)[0m 2021-05-02 00:45:23,335	ERROR function_runner.py:254 -- Runner Thread raised error.
[2m[36m(pid=11491)[0m Traceback (most recent call last):
[2m[36m(pid=11491)[0m   File "/zhome/45/c/127804/02460/python384/lib/python3.8/site-packages/ray/tune/function_runner.py", line 248, in run
[2m[36m(pid=11491)[0m     self._entrypoint()
[2m[36m(pid=11491)[0m   File "/zhome/45/c/127804/02460/python384/lib/python3.8/site-packages/ray/tune/function_runner.py", line 315, in entrypoint
[2m[36m(pid=11491)[0m     return self._trainable_func(self.config, self._status_reporter,
[2m[36m(pid=11491)[0m   File "/zhome/45/c/127804/02460/python384/lib/python3.8/site-packages/ray/tune/function_runner.py", line 580, in _trainable_func
[2m[36m(pid=11491)[0m     output = fn()
[2m[36m(pid=11491)[0m   File "grid_search_warm_up.py", line 94, in train_func
[2m[36m(pid=11491)[0m     loss, rl, kl      = vae.loss(x_hat, batch,p_mu,p_logvar,d_mu,d_logvar,alpha_warm_up =alpha_warm_up[k])
[2m[36m(pid=11491)[0m   File "/zhome/45/c/127804/02460/Variational_proteins/HVAE_v2.py", line 183, in loss
[2m[36m(pid=11491)[0m     p = Normal(p_mu[i], p_logvar[i].mul(1/2).exp())
[2m[36m(pid=11491)[0m   File "/zhome/45/c/127804/02460/python384/lib/python3.8/site-packages/torch/distributions/normal.py", line 50, in __init__
[2m[36m(pid=11491)[0m     super(Normal, self).__init__(batch_shape, validate_args=validate_args)
[2m[36m(pid=11491)[0m   File "/zhome/45/c/127804/02460/python384/lib/python3.8/site-packages/torch/distributions/distribution.py", line 53, in __init__
[2m[36m(pid=11491)[0m     raise ValueError("The parameter {} has invalid values".format(param))
[2m[36m(pid=11491)[0m ValueError: The parameter loc has invalid values
[2m[36m(pid=11491)[0m Exception in thread Thread-2:
[2m[36m(pid=11491)[0m Traceback (most recent call last):
[2m[36m(pid=11491)[0m   File "/appl/python/3.8.4/lib/python3.8/threading.py", line 932, in _bootstrap_inner
[2m[36m(pid=11491)[0m     self.run()
[2m[36m(pid=11491)[0m   File "/zhome/45/c/127804/02460/python384/lib/python3.8/site-packages/ray/tune/function_runner.py", line 267, in run
[2m[36m(pid=11491)[0m     raise e
[2m[36m(pid=11491)[0m   File "/zhome/45/c/127804/02460/python384/lib/python3.8/site-packages/ray/tune/function_runner.py", line 248, in run
[2m[36m(pid=11491)[0m     self._entrypoint()
[2m[36m(pid=11491)[0m   File "/zhome/45/c/127804/02460/python384/lib/python3.8/site-packages/ray/tune/function_runner.py", line 315, in entrypoint
[2m[36m(pid=11491)[0m     return self._trainable_func(self.config, self._status_reporter,
[2m[36m(pid=11491)[0m   File "/zhome/45/c/127804/02460/python384/lib/python3.8/site-packages/ray/tune/function_runner.py", line 580, in _trainable_func
[2m[36m(pid=11491)[0m     output = fn()
[2m[36m(pid=11491)[0m   File "grid_search_warm_up.py", line 94, in train_func
[2m[36m(pid=11491)[0m     loss, rl, kl      = vae.loss(x_hat, batch,p_mu,p_logvar,d_mu,d_logvar,alpha_warm_up =alpha_warm_up[k])
[2m[36m(pid=11491)[0m   File "/zhome/45/c/127804/02460/Variational_proteins/HVAE_v2.py", line 183, in loss
[2m[36m(pid=11491)[0m     p = Normal(p_mu[i], p_logvar[i].mul(1/2).exp())
[2m[36m(pid=11491)[0m   File "/zhome/45/c/127804/02460/python384/lib/python3.8/site-packages/torch/distributions/normal.py", line 50, in __init__
[2m[36m(pid=11491)[0m     super(Normal, self).__init__(batch_shape, validate_args=validate_args)
[2m[36m(pid=11491)[0m   File "/zhome/45/c/127804/02460/python384/lib/python3.8/site-packages/torch/distributions/distribution.py", line 53, in __init__
[2m[36m(pid=11491)[0m     raise ValueError("The parameter {} has invalid values".format(param))
[2m[36m(pid=11491)[0m ValueError: The parameter loc has invalid values
2021-05-02 00:45:23,419	ERROR trial_runner.py:732 -- Trial train_func_9c1c7_00048: Error processing event.
Traceback (most recent call last):
  File "/zhome/45/c/127804/02460/python384/lib/python3.8/site-packages/ray/tune/trial_runner.py", line 702, in _process_trial
    results = self.trial_executor.fetch_result(trial)
  File "/zhome/45/c/127804/02460/python384/lib/python3.8/site-packages/ray/tune/ray_trial_executor.py", line 686, in fetch_result
    result = ray.get(trial_future[0], timeout=DEFAULT_GET_TIMEOUT)
  File "/zhome/45/c/127804/02460/python384/lib/python3.8/site-packages/ray/_private/client_mode_hook.py", line 47, in wrapper
    return func(*args, **kwargs)
  File "/zhome/45/c/127804/02460/python384/lib/python3.8/site-packages/ray/worker.py", line 1481, in get
    raise value.as_instanceof_cause()
ray.exceptions.RayTaskError(TuneError): [36mray::ImplicitFunc.train_buffered()[39m (pid=11491, ip=10.66.20.3)
  File "python/ray/_raylet.pyx", line 505, in ray._raylet.execute_task
  File "python/ray/_raylet.pyx", line 449, in ray._raylet.execute_task.function_executor
  File "/zhome/45/c/127804/02460/python384/lib/python3.8/site-packages/ray/_private/function_manager.py", line 556, in actor_method_executor
    return method(__ray_actor, *args, **kwargs)
  File "/zhome/45/c/127804/02460/python384/lib/python3.8/site-packages/ray/tune/trainable.py", line 173, in train_buffered
    result = self.train()
  File "/zhome/45/c/127804/02460/python384/lib/python3.8/site-packages/ray/tune/trainable.py", line 232, in train
    result = self.step()
  File "/zhome/45/c/127804/02460/python384/lib/python3.8/site-packages/ray/tune/function_runner.py", line 366, in step
    self._report_thread_runner_error(block=True)
  File "/zhome/45/c/127804/02460/python384/lib/python3.8/site-packages/ray/tune/function_runner.py", line 512, in _report_thread_runner_error
    raise TuneError(
ray.tune.error.TuneError: Trial raised an exception. Traceback:
[36mray::ImplicitFunc.train_buffered()[39m (pid=11491, ip=10.66.20.3)
  File "/zhome/45/c/127804/02460/python384/lib/python3.8/site-packages/ray/tune/function_runner.py", line 248, in run
    self._entrypoint()
  File "/zhome/45/c/127804/02460/python384/lib/python3.8/site-packages/ray/tune/function_runner.py", line 315, in entrypoint
    return self._trainable_func(self.config, self._status_reporter,
  File "/zhome/45/c/127804/02460/python384/lib/python3.8/site-packages/ray/tune/function_runner.py", line 580, in _trainable_func
    output = fn()
  File "grid_search_warm_up.py", line 94, in train_func
    loss, rl, kl      = vae.loss(x_hat, batch,p_mu,p_logvar,d_mu,d_logvar,alpha_warm_up =alpha_warm_up[k])
  File "/zhome/45/c/127804/02460/Variational_proteins/HVAE_v2.py", line 183, in loss
    p = Normal(p_mu[i], p_logvar[i].mul(1/2).exp())
  File "/zhome/45/c/127804/02460/python384/lib/python3.8/site-packages/torch/distributions/normal.py", line 50, in __init__
    super(Normal, self).__init__(batch_shape, validate_args=validate_args)
  File "/zhome/45/c/127804/02460/python384/lib/python3.8/site-packages/torch/distributions/distribution.py", line 53, in __init__
    raise ValueError("The parameter {} has invalid values".format(param))
ValueError: The parameter loc has invalid values
2021-05-02 00:45:23,423	INFO logger.py:688 -- Removed the following hyperparameter values when logging to tensorboard: {'config/layers': (512, 512, 512), 'config/latents': (4, 4, 4)}
[2m[33m(raylet)[0m /zhome/45/c/127804/02460/python384/lib/python3.8/site-packages/ray/autoscaler/_private/cli_logger.py:57: FutureWarning: Not all Ray CLI dependencies were found. In Ray 1.4+, the Ray CLI, autoscaler, and dashboard will only be usable via `pip install 'ray[default]'`. Please update your install command.
[2m[33m(raylet)[0m   warnings.warn(
[2m[36m(pid=11533)[0m 2021-05-02 00:45:33,182	WARNING __init__.py:20 -- tune.track.log is now deprecated. Use `tune.report` instead. This warning will throw an error in a future version of Ray.
[2m[36m(pid=11533)[0m 2021-05-02 00:45:50,264	ERROR function_runner.py:254 -- Runner Thread raised error.
[2m[36m(pid=11533)[0m Traceback (most recent call last):
[2m[36m(pid=11533)[0m   File "/zhome/45/c/127804/02460/python384/lib/python3.8/site-packages/ray/tune/function_runner.py", line 248, in run
[2m[36m(pid=11533)[0m     self._entrypoint()
[2m[36m(pid=11533)[0m   File "/zhome/45/c/127804/02460/python384/lib/python3.8/site-packages/ray/tune/function_runner.py", line 315, in entrypoint
[2m[36m(pid=11533)[0m     return self._trainable_func(self.config, self._status_reporter,
[2m[36m(pid=11533)[0m   File "/zhome/45/c/127804/02460/python384/lib/python3.8/site-packages/ray/tune/function_runner.py", line 580, in _trainable_func
[2m[36m(pid=11533)[0m     output = fn()
[2m[36m(pid=11533)[0m   File "grid_search_warm_up.py", line 94, in train_func
[2m[36m(pid=11533)[0m     loss, rl, kl      = vae.loss(x_hat, batch,p_mu,p_logvar,d_mu,d_logvar,alpha_warm_up =alpha_warm_up[k])
[2m[36m(pid=11533)[0m   File "/zhome/45/c/127804/02460/Variational_proteins/HVAE_v2.py", line 183, in loss
[2m[36m(pid=11533)[0m     p = Normal(p_mu[i], p_logvar[i].mul(1/2).exp())
[2m[36m(pid=11533)[0m   File "/zhome/45/c/127804/02460/python384/lib/python3.8/site-packages/torch/distributions/normal.py", line 50, in __init__
[2m[36m(pid=11533)[0m     super(Normal, self).__init__(batch_shape, validate_args=validate_args)
[2m[36m(pid=11533)[0m   File "/zhome/45/c/127804/02460/python384/lib/python3.8/site-packages/torch/distributions/distribution.py", line 53, in __init__
[2m[36m(pid=11533)[0m     raise ValueError("The parameter {} has invalid values".format(param))
[2m[36m(pid=11533)[0m ValueError: The parameter loc has invalid values
[2m[36m(pid=11533)[0m Exception in thread Thread-2:
[2m[36m(pid=11533)[0m Traceback (most recent call last):
[2m[36m(pid=11533)[0m   File "/appl/python/3.8.4/lib/python3.8/threading.py", line 932, in _bootstrap_inner
2021-05-02 00:45:50,295	ERROR trial_runner.py:732 -- Trial train_func_9c1c7_00049: Error processing event.
Traceback (most recent call last):
  File "/zhome/45/c/127804/02460/python384/lib/python3.8/site-packages/ray/tune/trial_runner.py", line 702, in _process_trial
    results = self.trial_executor.fetch_result(trial)
  File "/zhome/45/c/127804/02460/python384/lib/python3.8/site-packages/ray/tune/ray_trial_executor.py", line 686, in fetch_result
    result = ray.get(trial_future[0], timeout=DEFAULT_GET_TIMEOUT)
  File "/zhome/45/c/127804/02460/python384/lib/python3.8/site-packages/ray/_private/client_mode_hook.py", line 47, in wrapper
    return func(*args, **kwargs)
  File "/zhome/45/c/127804/02460/python384/lib/python3.8/site-packages/ray/worker.py", line 1481, in get
    raise value.as_instanceof_cause()
ray.exceptions.RayTaskError(TuneError): [36mray::ImplicitFunc.train_buffered()[39m (pid=11533, ip=10.66.20.3)
  File "python/ray/_raylet.pyx", line 505, in ray._raylet.execute_task
  File "python/ray/_raylet.pyx", line 449, in ray._raylet.execute_task.function_executor
  File "/zhome/45/c/127804/02460/python384/lib/python3.8/site-packages/ray/_private/function_manager.py", line 556, in actor_method_executor
    return method(__ray_actor, *args, **kwargs)
  File "/zhome/45/c/127804/02460/python384/lib/python3.8/site-packages/ray/tune/trainable.py", line 173, in train_buffered
    result = self.train()
  File "/zhome/45/c/127804/02460/python384/lib/python3.8/site-packages/ray/tune/trainable.py", line 232, in train
    result = self.step()
  File "/zhome/45/c/127804/02460/python384/lib/python3.8/site-packages/ray/tune/function_runner.py", line 366, in step
    self._report_thread_runner_error(block=True)
  File "/zhome/45/c/127804/02460/python384/lib/python3.8/site-packages/ray/tune/function_runner.py", line 512, in _report_thread_runner_error
    raise TuneError(
ray.tune.error.TuneError: Trial raised an exception. Traceback:
[36mray::ImplicitFunc.train_buffered()[39m (pid=11533, ip=10.66.20.3)
  File "/zhome/45/c/127804/02460/python384/lib/python3.8/site-packages/ray/tune/function_runner.py", line 248, in run
    self._entrypoint()
  File "/zhome/45/c/127804/02460/python384/lib/python3.8/site-packages/ray/tune/function_runner.py", line 315, in entrypoint
    return self._trainable_func(self.config, self._status_reporter,
  File "/zhome/45/c/127804/02460/python384/lib/python3.8/site-packages/ray/tune/function_runner.py", line 580, in _trainable_func
    output = fn()
  File "grid_search_warm_up.py", line 94, in train_func
    loss, rl, kl      = vae.loss(x_hat, batch,p_mu,p_logvar,d_mu,d_logvar,alpha_warm_up =alpha_warm_up[k])
  File "/zhome/45/c/127804/02460/Variational_proteins/HVAE_v2.py", line 183, in loss
    p = Normal(p_mu[i], p_logvar[i].mul(1/2).exp())
  File "/zhome/45/c/127804/02460/python384/lib/python3.8/site-packages/torch/distributions/normal.py", line 50, in __init__
    super(Normal, self).__init__(batch_shape, validate_args=validate_args)
  File "/zhome/45/c/127804/02460/python384/lib/python3.8/site-packages/torch/distributions/distribution.py", line 53, in __init__
    raise ValueError("The parameter {} has invalid values".format(param))
ValueError: The parameter loc has invalid values
2021-05-02 00:45:50,300	INFO logger.py:688 -- Removed the following hyperparameter values when logging to tensorboard: {'config/layers': (512, 512, 512), 'config/latents': (4, 4, 8)}
[2m[36m(pid=11533)[0m     self.run()
[2m[36m(pid=11533)[0m   File "/zhome/45/c/127804/02460/python384/lib/python3.8/site-packages/ray/tune/function_runner.py", line 267, in run
[2m[36m(pid=11533)[0m     raise e
[2m[36m(pid=11533)[0m   File "/zhome/45/c/127804/02460/python384/lib/python3.8/site-packages/ray/tune/function_runner.py", line 248, in run
[2m[36m(pid=11533)[0m     self._entrypoint()
[2m[36m(pid=11533)[0m   File "/zhome/45/c/127804/02460/python384/lib/python3.8/site-packages/ray/tune/function_runner.py", line 315, in entrypoint
[2m[36m(pid=11533)[0m     return self._trainable_func(self.config, self._status_reporter,
[2m[36m(pid=11533)[0m   File "/zhome/45/c/127804/02460/python384/lib/python3.8/site-packages/ray/tune/function_runner.py", line 580, in _trainable_func
[2m[36m(pid=11533)[0m     output = fn()
[2m[36m(pid=11533)[0m   File "grid_search_warm_up.py", line 94, in train_func
[2m[36m(pid=11533)[0m     loss, rl, kl      = vae.loss(x_hat, batch,p_mu,p_logvar,d_mu,d_logvar,alpha_warm_up =alpha_warm_up[k])
[2m[36m(pid=11533)[0m   File "/zhome/45/c/127804/02460/Variational_proteins/HVAE_v2.py", line 183, in loss
[2m[36m(pid=11533)[0m     p = Normal(p_mu[i], p_logvar[i].mul(1/2).exp())
[2m[36m(pid=11533)[0m   File "/zhome/45/c/127804/02460/python384/lib/python3.8/site-packages/torch/distributions/normal.py", line 50, in __init__
[2m[36m(pid=11533)[0m     super(Normal, self).__init__(batch_shape, validate_args=validate_args)
[2m[36m(pid=11533)[0m   File "/zhome/45/c/127804/02460/python384/lib/python3.8/site-packages/torch/distributions/distribution.py", line 53, in __init__
[2m[36m(pid=11533)[0m     raise ValueError("The parameter {} has invalid values".format(param))
[2m[36m(pid=11533)[0m ValueError: The parameter loc has invalid values
[2m[33m(raylet)[0m /zhome/45/c/127804/02460/python384/lib/python3.8/site-packages/ray/autoscaler/_private/cli_logger.py:57: FutureWarning: Not all Ray CLI dependencies were found. In Ray 1.4+, the Ray CLI, autoscaler, and dashboard will only be usable via `pip install 'ray[default]'`. Please update your install command.
[2m[33m(raylet)[0m   warnings.warn(
[2m[36m(pid=11589)[0m 2021-05-02 00:45:59,980	WARNING __init__.py:20 -- tune.track.log is now deprecated. Use `tune.report` instead. This warning will throw an error in a future version of Ray.
2021-05-02 01:00:31,594	INFO logger.py:688 -- Removed the following hyperparameter values when logging to tensorboard: {'config/layers': (512, 512, 512), 'config/latents': (4, 4, 16)}
[2m[33m(raylet)[0m /zhome/45/c/127804/02460/python384/lib/python3.8/site-packages/ray/autoscaler/_private/cli_logger.py:57: FutureWarning: Not all Ray CLI dependencies were found. In Ray 1.4+, the Ray CLI, autoscaler, and dashboard will only be usable via `pip install 'ray[default]'`. Please update your install command.
[2m[33m(raylet)[0m   warnings.warn(
[2m[36m(pid=12468)[0m 2021-05-02 01:00:41,319	WARNING __init__.py:20 -- tune.track.log is now deprecated. Use `tune.report` instead. This warning will throw an error in a future version of Ray.
2021-05-02 01:15:17,680	INFO logger.py:688 -- Removed the following hyperparameter values when logging to tensorboard: {'config/layers': (512, 512, 512), 'config/latents': (4, 8, 8)}
User defined signal 2
